Workbook

Sheet 표지
B3: 전국 공공체육시설 현황
A9: (2024년말 기준)
A17: 2025
A23: 문 화 체 육 관 광 부

Sheet 일반개요
A1: 1. 기 준
A3: ㅇ 본 통계는 "체육시설의 설치ㆍ이용에 관한 법률" 제36조(시책 수립에 필요한 사항 등의 보고) 및 동법 시행규칙 제 28조(보고사항)에 따라 지방자치단체 등이 제출한 자료를 종합 정리한 것으로서, 2023년 12월말 기준으로 작성된 현황임(단, 건립중인 시설, 학교 교육만을 목적으로 하는 학교체육시설 등은 제외)
A5: 2. 체육시설의 정의
A7: 가. 학문적 정의
A8: ㅇ 효과적이며 보다 쾌적하고 안전한 운동활동을 전제로 설치 관리되는 일정한 공간적 범위를 가지는 물적 환경
A9: - 광의적 개념 : 운동에 필요한 물적인 여러가지 조건을 인공적으로 정비한 시설과 용기구 및 용품을 포함한 조형물
A10: - 협의적 개념 : 운동학습을 위한 각종의 장소
A12: 나. 법적 정의
A13: ㅇ 체육활동에 지속적으로 이용되는 시설과 그 부대시설(체육시설의 설치ㆍ이용에 관한 법률 제2조 제1호)
A14: ㅇ 건전한 신체ㆍ정신 함양과 여가 선용을 목적으로 운동경기ㆍ야외운동 등의 신체활동에 지속적으로 이용되는 시설과 그 부대시설(국민체육진흥법)
A15: * 체육 : 운동경기ㆍ야외운동 등 신체활동을 통하여 건전한 신체와 정신을 기르고 여가를 선용하는 것(국민체육진흥법 제2조)
A17: 3. 체육시설의 구분
... A35: ㅇ 직장체육시설 : 직장인의 체육활동에 필요한 체육시설(상시 근무 직장인이 500명 이상인 직장을 대상으로 함 : "체육시설의 설치ㆍ이용에 관한 법률" 제7조의 규정에 의함)

Sheet 공공체육시설의분류기준
A1: 5. 공공체육시설의 분류기준
A3: 시설항목 | B3: 시 설 분 류 기 준 | C3: 시설항목 | D3: 시 설 분 류 기 준
A4: 1. 육상경기장 | B4: 일주거리 400m 또는 300m, 200m의 육상트랙, 필드(축구경기장) 및 보조경기장 등을 갖춘 경기시설로서 종합운동장, 종합운동장 주경기장, 종합경기장 주경기장, 공설운동장, 시민운동장, ㅇㅇ경기장 등으로 일컬어짐 | C4: 12. 롤러스케이트장 - 정 규(트랙) - 정 규(로드) - 간 이 | D4: ㆍ트랙경기장 : 일주거리 200m의 트랙, 주폭 6m 이상 ㆍ로드경기장 : 250m~1,000m, 주폭 8m 이상 ㆍ경기장 규격이 정규수준에 미달되는 시설
A5: 2. 축구장 | B5: 길이 100~110m, 폭 64~75m(국제경기 규격) 또는 이와 유사한 규격 (축구 경기 가능시설로서, 육상경기장내의 축구경기장은 제외) | C5: 13. 사격장 | D5: 공기총사격(10m), 화약총사격(10m,25m,50m,300m), 클레이사격 (트랩,스키트)시설, 러닝 타겟 시설 중 전부 또는 일부를 보유한 사격장
A6: 3. 하키장 | B6: 길이 91.4m, 폭 55m 또는 이와 유사한 규격(하키 전용 경기장에 한함) | C6: 14. 국궁장 | D6: 사정거리는 관저 중심에서 사대 중심까지 145m, 과녁 사이 5m 이상 또는 이와 유사한 규격
A7: 4. 야구장 | B7: 본루로 부터 1,3루 측 야외거리가 98m 이상, 백스크린까지 110m이상 또는 이와 유사한 규격 | C7: 15. 양궁장 | D7: 30m, 50m, 60m, 70m, 90m 거리의 경기 가능
A8: 5. 싸이클경기장 | B8: 일주거리 실내 250~400m(통상 333.33m가 주종), 실외 250~500m , 주로 폭 7m 이상, 경사도 직선주로 8°~10°, 곡선주로 38°~45° | C8: 16. 승마장 | D8: 마장마술(길이 60m, 폭 20m), 장애물 비월(폭의 길이 최소한 60m 총 넓이 4,800㎡ 이상) 시설의 전부 또는 일부를 보유한 승마장
A9: 6. 테니스장 | B9: 가로 10.97m, 세로 23.77m (마을체육시설 수준의 테니스장은 간이 운동장으로 분류) | C9: 17. 골프연습장 | D9: 골프 연습 타석을 갖춘 시설
A10: 7. 씨름장 | B10: 경기장 높이 30㎝ 이상 70㎝ 이하, 경기장 직경 8m 이상인 원형의 모래시설과 경기장 밖 1.5m 이상의 보조경기장 또는 이와 유사한 규격 | C10: 18. 조정카누장 - 조 정 - 카 누 | D10: 조정 경기 가능 시설 카누 경기 가능 시설
A11: 8. 간이운동장 | B11: 축구, 배구, 농구, 테니스, 배드민턴, 게이트볼, 체력단련기구 등 간이운동시설이 설치된 거주지 인근의 마을체육시설 | C11: 19. 요트장 | D11: 요트 경기에 필요한 시설과 요트의 수납과 정비용 부대시설을 갖춘 경기장 또는 이와 유사한 경기장
A12: 9. 체육관 - 구기체육관 - 투기체육관 - 생활체육관 | B12: ㆍ 핸드볼, 농구, 배구, 배드민턴 등 구기 종목의 경기 개최가 가능한 체육관 ㆍ 유도, 레슬링, 복싱, 태권도, 펜싱, 검도, 씨름, 체조, 역도 등 투기종목의 경기 개최가 가능한 체육관 ㆍ 농구, 배구 등 구기 종목과 수영, 볼링, 에어로빅, 헬스 등 생활체육 종목의 각종 체육시설이 복합 설치된 체육관(올림픽 기념국민생활관, 국민체육센터, 시민체육관, 구민체육센터, 농어민 문화ㆍ체육센터, 농어촌 복합체육시설 등) | C12: 20. 빙상장 - 쇼트트랙 - 400M트랙 | D12: ㆍ 길이 60m, 폭 30m(일주거리 111.12m의 트랙)또는 이와 유사한 규격 (아이스하키 경기 가능) ㆍ 일주거리 400m이상 333.3m미만의 길이의 두개의 주로
A13: 10. 전천후 게이트볼장 | B13: 정식 규격의 게이트볼장으로 지붕, 기둥 또는 벽면으로 구성된 경기장(단, 지붕 구조가 막구조로 된 게이트볼장도 포함) | C13: 21. 설상경기장 - 스키점프장 - 바이애슬론경기장 - 크로스컨트리경기장 - 봅슬레이, 루지, 스켈레톤경기장 | D13: ㆍ 길이 90m, 120m 또는 이와 유사한 규격(스키점프 경기 가능) ㆍ 3.25km와 2km지점에 컷오프를 갖춘 하나의 4km 주로로 구성 ㆍ 5km×3코스=15km 또는 이와 유사한 규격(크로스컨트리 경기 가능) ㆍ 길이 1,200~1,650m 트랙을 갖춘 규격(1,200m 경사로)
A14: 11. 수 영 장 - 경영풀 - 다이빙풀 - 비정규 | B14: ㆍ폭 25m, 길이 50m 8레인으로 레인폭은 2.5m이상(1레인과 8레인 수영조 벽과 폭 0.5m 이상) 또는 이와 유사한 규격 ㆍ폭과 길이가 25m×33m, 수심 5m ㆍ경기장 규격이 정규수준에 미달되는 시설 | C14: 22. 기타 체육시설 | D14: ㆍ 상기 분류기준에 포함되지 않은 공공체육시설 - 파크골프장 - 풋살장 - 그외 시설

Sheet 연도별현황
A2: 시설항목 | B2: 2013년말 기준 | D2: 2014년말 기준 | F2: 2015년말 기준 | H2: 2017년말 기준 | J2: 2018년말 기준 | L2: 2019년말 기준 | N2: 2020년말 기준 | P2: 2021년말 기준 | R2: 2022년말 기준 | T2: 2023년말 기준 | V2: 2024년말 기준
B3: 개소 | C3: 면적 | D3: 개소 | E3: 면적 | F3: 개소 | G3: 면적 | H3: 개소 | I3: 면적 | J3: 개소 | K3: 면적 | L3: 개소 | M3: 면적 | N3: 개소 | O3: 면적 | P3: 개소 | Q3: 면적 | R3: 개소 | S3: 면적 | T3: 개소 | U3: 면적 | V3: 개소 | W3: 면적
A4: 합계 | B4: 19398 | C4: 1.38294e+08 | D4: 21317 | E4: 1.5111776e+08 | F4: 22662 | G4: 1.5608376e+08 | H4: 26927 | I4: 1.7761431e+08 | J4: 28578 | K4: 1.8875698e+08 | L4: 30185 | M4: 1.9805157e+08 | N4: 31554 | O4: 200616367 | P4: 33729 | Q4: 2.0450315e+08 | R4: 35941 | S4: 2.1972693e+08 | T4: 37176 | U4: 218321405 | V4: =설치주체별현황!B5 -> 38602 | W4: =설치주체별현황!C5 -> 2.3406574e+08 | X4: =V4-T4 -> 1426 | Y4: =W4-U4 -> 15744335
A5: 1. 육상경기장 | B5: 236 | C5: 18438579 | D5: 242 | E5: 19282025 | F5: 254 | G5: 19670038 | H5: 256 | I5: 20455381 | J5: 255 | K5: 20537112 | L5: 252 | M5: 20447703 | N5: 252 | O5: 20554056 | P5: 253 | Q5: 20688091 | R5: 247 | S5: 20548486 | T5: 246 | U5: 20717348 | V5: =[1]설치주체별현황!B6 -> 249 | W5: =[1]설치주체별현황!C6 -> 20596790 | X5: =V5-T5 -> 3
A6: 2. 축구장 | B6: 801 | C6: 22622357 | D6: 852 | E6: 24438600 | F6: 886 | G6: 25553891 | H6: 984 | I6: 30013006 | J6: 1019 | K6: 31111769 | L6: 1040 | M6: 31135673 | N6: 1064 | O6: 30711292 | P6: 1095 | Q6: 31712015 | R6: 1109 | S6: 32344365 | T6: 1146 | U6: 33051700 | V6: =[1]설치주체별현황!B7 -> 1163 | W6: =[1]설치주체별현황!C7 -> 33897030 | X6: =V6-T6 -> 17
A7: 3. 하키장 | B7: 15 | C7: 776717 | D7: 16 | E7: 1019201 | F7: 16 | G7: 1018172 | H7: 16 | I7: 1014641 | J7: 16 | K7: 1014414 | L7: 16 | M7: 1014414 | N7: 16 | O7: 888916 | P7: 17 | Q7: 888916 | R7: 19 | S7: 1167527 | T7: 18 | U7: 11696357 | V7: =[1]설치주체별현황!B8 -> 18 | W7: =[1]설치주체별현황!C8 -> 1169357 | X7: =V7-T7 -> 0
A8: 4. 야구장 | B8: 169 | C8: 5682942 | D8: 202 | E8: 6713426.1 | F8: 222 | G8: 7345269.1 | H8: 264 | I8: 7915878.2 | J8: 293 | K8: 9389310.1 | L8: 309 | M8: 9610609.1 | N8: 332 | O8: 10305677 | P8: 349 | Q8: 10659602 | R8: 352 | S8: 10719747 | T8: 359 | U8: 10560570 | V8: =[1]설치주체별현황!B9 -> 373 | W8: =[1]설치주체별현황!C9 -> 11201981 | X8: =V8-T8 -> 14
A9: 5. 싸이클경기장 | B9: 12 | C9: 460605 | D9: 12 | E9: 460605 | F9: 12 | G9: 460605 | H9: 11 | I9: 492640 | J9: 11 | K9: 492640 | L9: 11 | M9: 492640 | N9: 11 | O9: 492640 | P9: 11 | Q9: 492640 | R9: 11 | S9: 492640 | T9: 11 | U9: 496536 | V9: =[1]설치주체별현황!B10 -> 11 | W9: =[1]설치주체별현황!C10 -> 496536 | X9: =V9-T9 -> 0
A10: 6. 테니스장 | B10: 660 | C10: 6381572 | D10: 696 | E10: 7094796.6 | F10: 718 | G10: 7310504.6 | H10: 772 | I10: 7542350.1 | J10: 797 | K10: 7885330.9 | L10: 818 | M10: 8274015.9 | N10: 832 | O10: 9048946.8 | P10: 856 | Q10: 9818866 | R10: 873 | S10: 10008500 | T10: 898 | U10: 10294132 | V10: =[1]설치주체별현황!B11 -> 915 | W10: =[1]설치주체별현황!C11 -> 11419958 | X10: =V10-T10 -> 17
A11: 7. 씨름장 | B11: 45 | C11: 119747 | D11: 52 | E11: 134734.92 | F11: 54 | G11: 85823.92 | H11: 66 | I11: 221751.82 | J11: 66 | K11: 220349.82 | L11: 71 | M11: 224674.3 | N11: 73 | O11: 473792.7 | P11: 73 | Q11: 624901.7 | R11: 70 | S11: 624026.8 | T11: 72 | U11: 769021 | V11: =[1]설치주체별현황!B12 -> 73 | W11: =[1]설치주체별현황!C12 -> 1134433.8 | X11: =V11-T11 -> 1
A12: 8. 간이운동장 (마을체육시설) | B12: 14536 | C12: 45455263 | D12: 16046 | E12: 47586089 | F12: 17111 | G12: 48710747 | H12: 20602 | I12: 54703992 | J12: 21847 | K12: 59268363 | L12: 22866 | M12: 60015081 | N12: 23834 | O12: 57942133 | P12: 25455 | Q12: 54041409 | R12: 25983 | S12: 53585239 | T12: 26838 | U12: 48558250 | V12: =[1]설치주체별현황!B13 -> 27850 | W12: =[1]설치주체별현황!C13 -> 48877134 | X12: =V12-T12 -> 1012
A13: 9. 체육관 | B13: 819 | C13: 17305295 | D13: 875 | E13: 19172305 | F13: 905 | G13: 19914390 | H13: 1010 | I13: 22650854 | J13: 1066 | K13: 23361098 | L13: 1139 | M13: 25368827 | N13: 1194 | O13: 26680519 | P13: 1275 | Q13: 29053094 | R13: 1337 | S13: 31251139 | T13: 1439 | U13: 33342939 | V13: =[1]설치주체별현황!B14 -> 1530 | W13: =[1]설치주체별현황!C14 -> 36302920 | X13: =V13-T13 -> 91
A14: - 구기체육관 | B14: 355 | C14: 7265923 | D14: 379 | E14: 7976599.4 | F14: 390 | G14: 8138934.7 | H14: 427 | I14: 9096302.2 | J14: 444 | K14: 9298951.6 | L14: 471 | M14: 10432582 | N14: 487 | O14: 10620191 | P14: 516 | Q14: 11357044 | R14: 524 | S14: 12046222 | T14: 547 | U14: 12574684 | V14: =[1]설치주체별현황!B15 -> 559 | W14: =[1]설치주체별현황!C15 -> 12917875 | X14: =V14-T14 -> 12
A15: - 투기체육관 | B15: 46 | C15: 346069 | D15: 47 | E15: 669636.2 | F15: 48 | G15: 682063.2 | H15: 47 | I15: 687023.2 | J15: 46 | K15: 684417.2 | L15: 46 | M15: 748684.75 | N15: 46 | O15: 777593.75 | P15: 47 | Q15: 878475.65 | R15: 48 | S15: 1135475.6 | T15: 48 | U15: 1142797 | V15: =[1]설치주체별현황!B16 -> 48 | W15: =[1]설치주체별현황!C16 -> 1493303.4 | X15: =V15-T15 -> 0
A16: - 생활체육관 | B16: 418 | C16: 9693302 | D16: 449 | E16: 10526069 | F16: 467 | G16: 11093392 | H16: 536 | I16: 12867528 | J16: 576 | K16: 13377729 | L16: 622 | M16: 14187560 | N16: 661 | O16: 15282735 | P16: 712 | Q16: 16817574 | R16: 765 | S16: 18069441 | T16: 844 | U16: 19625457 | V16: =[1]설치주체별현황!B17 -> 923 | W16: =[1]설치주체별현황!C17 -> 21891742 | X16: =V16-T16 -> 79
... A21: 14. 국궁장 | B21: 249 | C21: 2119137 | D21: 251 | E21: 2166602.5 | F21: 252 | G21: 2246215.5 | H21: 264 | I21: 2575790.5 | J21: 273 | K21: 2643627.5 | L21: 280 | M21: 2865230.5 | N21: 281 | O21: 2909238.5 | P21: 282 | Q21: 2845512.5 | R21: 284 | S21: 2878812.5 | T21: 284 | U21: 2993779 | V21: =[1]설치주체별현황!B22 -> 285 | W21: =[1]설치주체별현황!C22 -> 2942923.5 | X21: =V21-T21 -> 1
A22: 15. 양궁장 | B22: 21 | C22: 506909 | D22: 22 | E22: 529349 | F22: 23 | G22: 574458 | H22: 24 | I22: 582522 | J22: 25 | K22: 656205 | L22: 24 | M22: 653685 | N22: 25 | O22: 656532 | P22: 26 | Q22: 666569 | R22: 26 | S22: 666569 | T22: 28 | U22: 672869 | V22: =시도별현황!B21 -> 28 | W22: =[1]설치주체별현황!C23 -> 678141 | X22: =V22-T22 -> 0
A23: 16. 승마장 | B23: 17 | C23: 818024 | D23: 18 | E23: 839836.12 | F23: 19 | G23: 839836.12 | H23: 20 | I23: 842543.92 | J23: 20 | K23: 842543.92 | L23: 19 | M23: 829851.92 | N23: 20 | O23: 1002627.9 | P23: 22 | Q23: 1018336.9 | R23: 23 | S23: 1057398 | T23: 24 | U23: 1089062 | V23: =[1]설치주체별현황!B24 -> 24 | W23: =[1]설치주체별현황!C24 -> 1065286 | X23: =V23-T23 -> 0
A24: 17. 골프연습장 | B24: 73 | C24: 338802 | D24: 74 | E24: 474659.7 | F24: 74 | G24: 474659.7 | H24: 83 | I24: 798856.9 | J24: 84 | K24: 810200.9 | L24: 89 | M24: 916913.9 | N24: 89 | O24: 961562.9 | P24: 94 | Q24: 1035121.9 | R24: 91 | S24: 1070727.9 | T24: 92 | U24: 1260755 | V24: =[1]설치주체별현황!B25 -> 92 | W24: =[1]설치주체별현황!C25 -> 1340909.4 | X24: =V24-T24 -> 0
A25: 18. 조정카누장 | B25: 11 | C25: 1307255 | D25: 11 | E25: 1307989 | F25: 11 | G25: 1203094 | H25: 11 | I25: 1203094 | J25: 11 | K25: 1203094 | L25: 11 | M25: 1203094 | N25: 10 | O25: 1197279 | P25: 10 | Q25: 1197279 | R25: 10 | S25: 1197279 | T25: 10 | U25: 1197279 | V25: =[1]설치주체별현황!B26 -> 10 | W25: =[1]설치주체별현황!C26 -> 1197279 | X25: =V25-T25 -> 0
A26: 19. 요트장 | B26: 17 | C26: 322289 | D26: 17 | E26: 322289 | F26: 17 | G26: 322839 | H26: 17 | I26: 322319 | J26: 17 | K26: 322319 | L26: 17 | M26: 322319 | N26: 17 | O26: 322319 | P26: 16 | Q26: 316758 | R26: 16 | S26: 316758 | T26: 16 | U26: 316758 | V26: =[1]설치주체별현황!B27 -> 15 | W26: =[1]설치주체별현황!C27 -> 315018 | X26: =V26-T26 -> -1
A27: 20. 빙상장 | B27: 21 | C27: 239817 | D27: 21 | E27: 260535 | F27: 22 | G27: 272494 | H27: 29 | I27: 1186940 | J27: 30 | K27: 1270062 | L27: 31 | M27: 1309119 | N27: 32 | O27: 1304969 | P27: 33 | Q27: 1552045 | R27: 34 | S27: 1446116 | T27: 34 | U27: 1446116 | V27: =[1]설치주체별현황!B28 -> 36 | W27: =[1]설치주체별현황!C28 -> 3745426.6 | X27: =V27-T27 -> 2
A28: 21. 설상경기장 | B28: 3 | C28: 315669 | D28: 3 | E28: 313173 | F28: 3 | G28: 313173 | H28: 4 | I28: 462499.9 | J28: 4 | K28: 462499.9 | L28: 4 | M28: 462499.9 | N28: 4 | O28: 462499.9 | P28: 4 | Q28: 462499.9 | R28: 4 | S28: 462499.9 | T28: 4 | U28: 462500 | V28: =[1]설치주체별현황!B29 -> 4 | W28: =[1]설치주체별현황!C29 -> 462499.9 | X28: =V28-T28 -> 0
A29: 22. 파크골프장 | T29: 346 | U29: 6728131 | V29: =시도별현황!B28 -> 461 | W29: =[1]설치주체별현황!C30 -> 8596930.3 | X29: =V29-T29 -> 115
A30: 23. 기타 시설 | B30: 107 | C30: 3489869 | D30: 157 | E30: 5412665.1 | F30: 226 | G30: 5083612.1 | H30: 426 | I30: 7721386.4 | J30: 531 | K30: 9523053.7 | L30: 792 | M30: 13044079 | N30: 961 | O30: 14189081 | P30: 1267 | Q30: 16070778 | R30: 2766 | S30: 26646124 | T30: 2586 | U30: 25464041 | V30: =[1]설치주체별현황!B31 -> 2677 | W30: =[1]설치주체별현황!C31 -> 19598994 | X30: =V30-T30 -> 91
A31: -풋살장 | T31: 557 | U31: 4458764 | V31: =시도별현황!B30 -> 630 | W31: =[1]설치주체별현황!C32 -> 5384145.7 | X31: =V31-T31 -> 73
A32: -그외 기타 | T32: 2022 | U32: 14277146 | V32: =[1]설치주체별현황!B33 -> 2046 | W32: =[1]설치주체별현황!C33 -> 14214848 | X32: =V32-T32 -> 24
A33: * 연도별 현황은 전년도 12월31일 기준 작성, 당해연도 1월1일 기준으로 공포

Sheet 설치주체별현황
A1: 1. 설치 주체별 시설 현황
A3: 시설항목 | B3: 전국 | D3: 지방자치단체 | F3: 대한체육회 | H3: 대한장애인체육회 | J3: 국민체육진흥공단 | L3: 비 고
B4: 개소 | C4: 면적 | D4: 개소 | E4: 면적 | F4: 개소 | G4: 면적 | H4: 개소 | I4: 면적 | J4: 개소 | K4: 면적
A5: 합계 | B5: =시도별현황!B3 -> 38602 | C5: =시도별현황!C3 -> 2.3406574e+08 | D5: =SUM(D6:D14,D18:D31) -> 38561 | E5: =SUM(E6:E14,E18:E31) -> 2.3135836e+08 | F5: =SUM(F6:F14,F18:F31) -> 16 | G5: =SUM(G6:G14,G18:G31) -> 1386280 | H5: =SUM(H6:H14,H18:H31) -> 10 | I5: =SUM(I6:I14,I18:I31) -> 209043 | J5: =SUM(J6:J14,J18:J31) -> 16 | K5: =SUM(K6:K14,K18:K31) -> 1113277
A6: 1. 육상경기장 | B6: =[1]시도별현황!B4 -> 249 | C6: =[1]시도별현황!C4 -> 20596790 | D6: =B6-F6-H6 -> 246 | E6: =C6-G6-I6 -> 20502947 | F6: 2 | G6: 80843 | H6: 1 | I6: 13000
A7: 2. 축구장 | B7: =[1]시도별현황!B5 -> 1163 | C7: =[1]시도별현황!C5 -> 33897030 | D7: =B7-F7-H7-J7 -> 1161 | E7: =C7-G7-I7-K7 -> 33804703 | F7: 1 | G7: 7140 | H7: 1 | I7: 85187
A8: 3. 하키장 | B8: =[1]시도별현황!B6 -> 18 | C8: =[1]시도별현황!C6 -> 1169357 | D8: =B8-F8 -> 16 | E8: =C8-G8 -> 973156 | F8: 2 | G8: 196201
A9: 4. 야구장 | B9: =[1]시도별현황!B7 -> 373 | C9: =[1]시도별현황!C7 -> 11201981 | D9: =B9-F9 -> 372 | E9: =C9-G9 -> 10160801 | F9: 1 | G9: 1041180
A10: 5. 싸이클경기장 | B10: =[1]시도별현황!B8 -> 11 | C10: =[1]시도별현황!C8 -> 496536 | D10: =B10-J10 -> 10 | E10: =C10-K10 -> 485864 | J10: 1 | K10: 10672
A11: 6. 테니스장 | B11: =[1]시도별현황!B9 -> 915 | C11: =[1]시도별현황!C9 -> 11419958 | D11: =B11-F11-H11-J11 -> 909 | E11: =C11-G11-I11-K11 -> 11382305 | F11: 3 | G11: 18595 | H11: 1 | I11: 5000 | J11: 2 | K11: 14058
A12: 7. 씨름장 | B12: =[1]시도별현황!B10 -> 73 | C12: =[1]시도별현황!C10 -> 1134433.8 | D12: =B12 -> 73 | E12: =C12 -> 1134433.8
A13: 8. 간이운동장 (마을체육시설) | B13: =[1]시도별현황!B11 -> 27850 | C13: =[1]시도별현황!C11 -> 48877134 | D13: =B13 -> 27850 | E13: =C13 -> 48877134
A14: 9. 체육관 | B14: =SUM(B15:B17) -> 1530 | C14: =SUM(C15:C17) -> 36302920 | D14: =B14-F14-H14-J14 -> 1517 | E14: =C14-G14-I14-K14 -> 36119946 | F14: =SUM(F15:F17) -> 3 | G14: =SUM(G15:G17) -> 10229 | H14: =SUM(H15:H17) -> 5 | I14: =SUM(I15:I17) -> 101856 | J14: 5 | K14: 70889
A15: 구기체육관 | B15: =[1]시도별현황!B13 -> 559 | C15: =[1]시도별현황!C13 -> 12917875 | D15: =B15-F15-H15-J15 -> 552 | E15: =C15-G15-I15-K15 -> 12762159 | F15: 2 | G15: 6606 | H15: 3 | I15: 99290 | J15: 2 | K15: 49820
A16: 투기체육관 | B16: =[1]시도별현황!B14 -> 48 | C16: =[1]시도별현황!C14 -> 1493303.4 | D16: =B16-F16-J16 -> 46 | E16: =C16-G16-I16-K16 -> 1474297.4 | F16: 1 | G16: 3623 | H16: 1 | I16: 2566 | J16: 1 | K16: 12817
A17: 생활체육관 | B17: =[1]시도별현황!B15 -> 923 | C17: =[1]시도별현황!C15 -> 21891742 | D17: =B17-H17-J17 -> 920 | E17: =C17-K17 -> 21883490 | H17: 1 | J17: 2 | K17: 8252 | L17: 장애인체육회: 구기 체육관 포함
A18: 10. 전천후게이트볼장 | B18: =[1]시도별현황!B16 -> 2000 | C18: =[1]시도별현황!C16 -> 11977087 | D18: =B18 -> 2000 | E18: =C18 -> 11977087
A19: 11. 수영장 | B19: =[1]시도별현황!B17 -> 579 | C19: =[1]시도별현황!C17 -> 13272657 | D19: =B19-F19-H19-J19 -> 574 | E19: =C19-G19-K19-I19 -> 13232834 | F19: 1 | G19: 8794 | H19: 1 | I19: 3000 | J19: 3 | K19: 28029 | L19: 장애인체육회: 구기 체육관 포함
A20: 12. 롤러스케이트장 | B20: =[1]시도별현황!B18 -> 184 | C20: =[1]시도별현황!C18 -> 2637650.6 | D20: =B20 -> 184 | E20: =C20 -> 2637650.6
A21: 13. 사격장 | B21: =[1]시도별현황!B19 -> 26 | C21: =[1]시도별현황!C19 -> 1083972 | D21: =B21-F21 -> 26 | E21: =C21-G21 -> 1083972
A22: 14. 국궁장 | B22: =[1]시도별현황!B20 -> 285 | C22: =[1]시도별현황!C20 -> 2942923.5 | D22: =B22 -> 285 | E22: =C22 -> 2942923.5
A23: 15. 양궁장 | B23: =시도별현황!B21 -> 28 | C23: =시도별현황!C21 -> 743211 | D23: =B23-H23 -> 27 | E23: =C23-I23 -> 742211 | H23: 1 | I23: 1000 | L23: 장애인체육회: 구기 체육관 포함
A24: 16. 승마장 | B24: =[1]시도별현황!B22 -> 24 | C24: =[1]시도별현황!C22 -> 1065286 | D24: =B24 -> 24 | E24: =C24 -> 1065286
A25: 17. 골프연습장 | B25: =[1]시도별현황!B23 -> 92 | C25: =[1]시도별현황!C23 -> 1340909.4 | D25: =B25-J25 -> 90 | E25: =C25-K25 -> 1339907.4 | J25: 2 | K25: 1002
A26: 18. 조정카누장 | B26: =[1]시도별현황!B24 -> 10 | C26: =[1]시도별현황!C24 -> 1197279 | D26: =B26-F26-J26 -> 8 | E26: =C26-G26-K26 -> 211635 | F26: 1 | G26: 734 | J26: 1 | K26: 984910
A27: 19. 요트장 | B27: =[1]시도별현황!B25 -> 15 | C27: =[1]시도별현황!C25 -> 315018 | D27: =B27 -> 15 | E27: =C27 -> 315018
A28: 20. 빙상장 | B28: =[1]시도별현황!B26 -> 36 | C28: =[1]시도별현황!C26 -> 3745426.6 | D28: =B28-F28-J28 -> 33 | E28: =C28-G28 -> 3722862.6 | F28: 2 | G28: 22564 | J28: 1 | K28: - | L28: 공단: 분당스포츠센터 포함
A29: 21. 설상경기장 | B29: =[1]시도별현황!B27 -> 4 | C29: =[1]시도별현황!$C$27 -> 462499.9 | D29: =B29 -> 4 | E29: =C29 -> 462499.9
A30: 22. 파크골프장 | B30: =시도별현황!B28 -> 461 | C30: =시도별현황!C28 -> 8587905.3 | D30: =B30-J30 -> 461 | E30: =C30-K30 -> 8587905.3
A31: 23. 기타 시설 | B31: =[1]시도별현황!B29 -> 2677 | C31: =[1]시도별현황!C29 -> 19598994 | D31: =B31-J31 -> 2676 | E31: =C31-K31 -> 19595277 | J31: 1 | K31: 3717 | L31: 공단: 일산올림픽스포츠센터 인공암벽장
A32: - 풋살장 | B32: =시도별현황!B30 -> 630 | C32: =시도별현황!C30 -> 5382925.7 | D32: =B32-J32 -> 630 | E32: =C32-K32 -> 5382925.7
A33: - 그외 | B33: =[1]시도별현황!B31 -> 2046 | C33: =[1]시도별현황!C31 -> 14214848 | D33: =B33-J33 -> 2045 | E33: =C33-K33 -> 14211131 | J33: 1 | K33: 3717

Sheet 시도별현황
A1: 시 설 항 목 | B1: 전국 | D1: 서울 | F1: 부산 | H1: 대구 | J1: 인천 | L1: 광주 | N1: 대전 | P1: 울산 | R1: 세종
B2: 개소 | C2: 면적 | D2: 개소 | E2: 면적 | F2: 개소 | G2: 면적 | H2: 개소 | I2: 면적 | J2: 개소 | K2: 면적 | L2: 개소 | M2: 면적 | N2: 개소 | O2: 면적 | P2: 개소 | Q2: 면적 | R2: 개소 | S2: 면적
A3: 합 계 | B3: =SUM(B4:B12,B16:B29) -> 38602 | C3: =SUM(C4:C12,C16:C29) -> 2.3406574e+08 | D3: =SUM(D4:D12,D16:D29) -> 3254 | E3: =SUM(E4:E12,E16:E29) -> 15580376 | F3: =SUM(F4:F12,F16:F29) -> 1908 | G3: =SUM(G4:G12,G16:G29) -> 5697504.9 | H3: =SUM(H4:H12,H16:H29) -> 1011 | I3: =SUM(I4:I12,I16:I29) -> 5271497.8 | ... S3: =SUM(S4:S12,S16:S29) -> 1560973
A4: 1. 육상경기장 | B4: =SUM(D4,F4,H4,J4,L4,N4,P4,R4,B35,D35,F35,H35,J35,L35,N35,P35,R35) -> 249 | C4: =SUM(E4,G4,I4,K4,M4,O4,Q4,S4,C35,E35,G35,I35,K35,M35,O35,Q35,S35) -> 20596790 | D4: =[1]육상경기장!E6 -> 3 | E4: =[1]육상경기장!L6 -> 249613 | F4: =[1]육상경기장!E10 -> 3 | G4: =[1]육상경기장!L10 -> 144597 | H4: =[1]육상경기장!E14 -> 5 | I4: =[1]육상경기장!L14 -> 708147 | J4: =[1]육상경기장!E20 -> 10 | K4: =[1]육상경기장!L20 -> 1305232 | L4: =[1]육상경기장!E31 -> 2 | M4: =[1]육상경기장!L31 -> 470278 | P4: =[1]육상경기장!E34 -> 6 | Q4: =[1]육상경기장!L34 -> 319484 | R4: =[1]육상경기장!E41 -> 1 | S4: =[1]육상경기장!N41 -> 400
A5: 2. 축구장 | B5: =SUM(D5,F5,H5,J5,L5,N5,P5,R5,B36,D36,F36,H36,J36,L36,N36,P36,R36) -> 1163 | C5: =SUM(E5,G5,I5,K5,M5,O5,Q5,S5,C36,E36,G36,I36,K36,M36,O36,Q36,S36) -> 33897030 | D5: =[1]축구장!E6 -> 74 | E5: =[1]축구장!I6 -> 926990 | F5: =[1]축구장!E81 -> 33 | G5: =[1]축구장!I81 -> 513731 | H5: =[1]축구장!E115 -> 39 | I5: =[1]축구장!I115 -> 702769 | J5: =[1]축구장!E155 -> 34 | K5: =[1]축구장!I155 -> 1068675.3 | L5: =[1]축구장!E190 -> 25 | M5: =[1]축구장!I190 -> 317524 | N5: =[1]축구장!E216 -> 14 | O5: =[1]축구장!I216 -> 536398.2 | P5: =[1]축구장!E231 -> 28 | Q5: =[1]축구장!I231 -> 1775842.3 | R5: =[1]축구장!E260 -> 13 | S5: =[1]축구장!I260 -> 241232
A6: 3. 하키장 | B6: =SUM(D6,F6,H6,J6,L6,N6,P6,R6,B37,D37,F37,H37,J37,L37,N37,P37,R37) -> 18 | C6: =SUM(E6,G6,I6,K6,M6,O6,Q6,S6,C37,E37,G37,I37,K37,M37,O37,Q37,S37) -> 1169357 | D6: =[1]하키장!E6 -> 1 | E6: =[1]하키장!J6 -> 183879 | F6: =[1]하키장!E8 -> 1 | G6: =[1]하키장!J8 -> 18310 | H6: =[1]하키장!E10 -> 1 | I6: =[1]하키장!J10 -> 50760 | J6: =[1]하키장!E12 -> 2 | K6: =[1]하키장!J12 -> 255935
A7: 4. 야구장 | B7: =SUM(D7,F7,H7,J7,L7,N7,P7,R7,B38,D38,F38,H38,J38,L38,N38,P38,R38) -> 373 | C7: =SUM(E7,G7,I7,K7,M7,O7,Q7,S7,C38,E38,G38,I38,K38,M38,O38,Q38,S38) -> 11201981 | D7: =[1]야구장!E6 -> 23 | E7: =[1]야구장!J6 -> 335191 | F7: =[1]야구장!E30 -> 11 | G7: =[1]야구장!J30 -> 402148 | H7: =[1]야구장!E42 -> 16 | I7: =[1]야구장!J42 -> 544293 | J7: =[1]야구장!E59 -> 9 | K7: =[1]야구장!J59 -> 842328.5 | L7: =[1]야구장!E69 -> 11 | M7: =[1]야구장!J69 -> 199546 | N7: =[1]야구장!E81 -> 7 | O7: =[1]야구장!J81 -> 5788.23 | P7: =[1]야구장!E89 -> 5 | Q7: =[1]야구장!J89 -> 110196 | R7: =[1]야구장!E95 -> 7 | S7: =[1]야구장!J95 -> 71427
A8: 5. 싸이클경기장 | B8: =SUM(D8,F8,H8,J8,L8,N8,P8,R8,B39,D39,F39,H39,J39,L39,N39,P39,R39) -> 11 | C8: =SUM(E8,G8,I8,K8,M8,O8,Q8,S8,C39,E39,G39,I39,K39,M39,O39,Q39,S39) -> 496536 | D8: 1 | E8: =[1]싸이클경기장!L6 -> 10672 | F8: 1 | G8: =[1]싸이클경기장!L7 -> 31861 | H8: 1 | I8: =[1]싸이클경기장!L8 -> 46972 | J8: 1 | K8: =[1]싸이클경기장!L9 -> 59356 | N8: 1 | O8: =[1]싸이클경기장!L10 -> 59499
A9: 6. 테니스장 | B9: =SUM(D9,F9,H9,J9,L9,N9,P9,R9,B40,D40,F40,H40,J40,L40,N40,P40,R40) -> 915 | C9: =SUM(E9,G9,I9,K9,M9,O9,Q9,S9,C40,E40,G40,I40,K40,M40,O40,Q40,S40) -> 11419958 | D9: =[1]테니스장!E5 -> 76 | E9: =[1]테니스장!K5 -> 441533.69 | F9: =[1]테니스장!E82 -> 41 | G9: =[1]테니스장!K82 -> 305711.95 | H9: =[1]테니스장!E124 -> 32 | I9: =[1]테니스장!K124 -> 441537 | J9: =[1]테니스장!E157 -> 40 | K9: =[1]테니스장!K157 -> 943918.9 | L9: =[1]테니스장!E198 -> 20 | M9: =[1]테니스장!K198 -> 107667 | N9: =[1]테니스장!E219 -> 8 | O9: =[1]테니스장!K219 -> 194841 | P9: =[1]테니스장!E228 -> 19 | Q9: =[1]테니스장!K228 -> 263473 | R9: =[1]테니스장!E248 -> 8 | S9: =[1]테니스장!K248 -> 110581
A10: 7. 씨름장 | B10: =SUM(D10,F10,H10,J10,L10,N10,P10,R10,B41,D41,F41,H41,J41,L41,N41,P41,R41) -> 73 | C10: =SUM(E10,G10,I10,K10,M10,O10,Q10,S10,C41,E41,G41,I41,K41,M41,O41,Q41,S41) -> 1134433.8 | F10: =[1]씨름장!E6 -> 2 | G10: =[1]씨름장!H6 -> 3687 | H10: =[1]씨름장!E9 -> 3 | I10: =[1]씨름장!H9 -> 9197 | J10: 1 | K10: =[1]씨름장!H13 -> 6188 | L10: 1 | M10: =[1]씨름장!H14 -> 234 | P10: 1 | Q10: =[1]씨름장!H15 -> 308269
A11: 8. 간이운동장 (마을체육시설) | B11: =SUM(D11,F11,H11,J11,L11,N11,P11,R11,B42,D42,F42,H42,J42,L42,N42,P42,R42) -> 27850 | C11: =SUM(E11,G11,I11,K11,M11,O11,Q11,S11,C42,E42,G42,I42,K42,M42,O42,Q42,S42) -> 48877134 | D11: 2538 | E11: 9895607.8 | F11: 1576 | G11: 2152163 | H11: 760 | I11: 966216 | J11: 989 | K11: 2425278.2 | L11: 1043 | M11: 515572 | N11: 557 | O11: 366023 | P11: 263 | Q11: 517305 | R11: 50 | S11: 68644
A12: 9. 체육관 | B12: =SUM(D12,F12,H12,J12,L12,N12,P12,R12,B43,D43,F43,H43,J43,L43,N43,P43,R43) -> 1530 | C12: =SUM(E12,G12,I12,K12,M12,O12,Q12,S12,C43,E43,G43,I43,K43,M43,O43,Q43,S43) -> 36302920 | D12: =SUM(D13:D15) -> 166 | E12: =SUM(E13:E15) -> 1859035.6 | F12: =SUM(F13:F15) -> 38 | G12: =SUM(G13:G15) -> 528927.56 | H12: =SUM(H13:H15) -> 36 | I12: =SUM(I13:I15) -> 447573 | J12: =SUM(J13:J15) -> 51 | K12: =SUM(K13:K15) -> 2494945.6 | ... S12: =SUM(S13:S15) -> 276105
A13: 구기체육관 | B13: =SUM(D13,F13,H13,J13,L13,N13,P13,R13,B44,D44,F44,H44,J44,L44,N44,P44,R44) -> 559 | C13: =SUM(E13,G13,I13,K13,M13,O13,Q13,S13,C44,E44,G44,I44,K44,M44,O44,Q44,S44) -> 12917875 | D13: =[1]구기체육관!E5 -> 51 | E13: =[1]구기체육관!H5 -> 668283.4 | F13: =[1]구기체육관!E57 -> 4 | G13: =[1]구기체육관!H57 -> 114089 | H13: =[1]구기체육관!E62 -> 4 | I13: =[1]구기체육관!H62 -> 30683 | J13: =[1]구기체육관!E67 -> 4 | K13: =[1]구기체육관!H67 -> 327698 | L13: =[1]구기체육관!E72 -> 3 | M13: =[1]구기체육관!H72 -> 55000 | N13: =[1]구기체육관!E76 -> 8 | O13: =[1]구기체육관!H76 -> 51698 | P13: =[1]구기체육관!E85 -> 7 | Q13: =[1]구기체육관!H85 -> 136299.2 | R13: =[1]구기체육관!E93 -> 2 | S13: =[1]구기체육관!H93 -> 4610
A14: 투기체육관 | B14: =SUM(D14,F14,H14,J14,L14,N14,P14,R14,B45,D45,F45,H45,J45,L45,N45,P45,R45) -> 48 | C14: =SUM(E14,G14,I14,K14,M14,O14,Q14,S14,C45,E45,G45,I45,K45,M45,O45,Q45,S45) -> 1493303.4 | D14: =[1]투기체육관!E5 -> 1 | E14: =[1]투기체육관!K5 -> 12817 | F14: =[1]투기체육관!E7 -> 2 | G14: =[1]투기체육관!K7 -> 6893 | H14: =[1]투기체육관!E10 -> 4 | I14: =[1]투기체육관!K10 -> 5725 | J14: =[1]투기체육관!E15 -> 3 | K14: =[1]투기체육관!K15 -> 357431 | L14: =[1]투기체육관!E19 -> 1 | M14: =[1]투기체육관!K19 -> 1576
A15: 생활체육관 | B15: =SUM(D15,F15,H15,J15,L15,N15,P15,R15,B46,D46,F46,H46,J46,L46,N46,P46,R46) -> 923 | C15: =SUM(E15,G15,I15,K15,M15,O15,Q15,S15,C46,E46,G46,I46,K46,M46,O46,Q46,S46) -> 21891742 | D15: =[1]생활체육관!E6 -> 114 | E15: =[1]생활체육관!H6 -> 1177935.2 | F15: =[1]생활체육관!E121 -> 32 | G15: =[1]생활체육관!H121 -> 407945.56 | H15: =[1]생활체육관!E154 -> 28 | I15: =[1]생활체육관!H154 -> 411165 | J15: =[1]생활체육관!E183 -> 44 | K15: =[1]생활체육관!H183 -> 1809816.6 | L15: =[1]생활체육관!E228 -> 25 | M15: =[1]생활체육관!H228 -> 306315.3 | N15: =[1]생활체육관!E254 -> 17 | O15: =[1]생활체육관!H254 -> 317270.7 | P15: =[1]생활체육관!E272 -> 16 | Q15: =[1]생활체육관!H272 -> 508116 | R15: =[1]생활체육관!E289 -> 25 | S15: =[1]생활체육관!H289 -> 271495
A16: 10. 전천후게이트볼장 | B16: =SUM(D16,F16,H16,J16,L16,N16,P16,R16,B47,D47,F47,H47,J47,L47,N47,P47,R47) -> 2000 | C16: =SUM(E16,G16,I16,K16,M16,O16,Q16,S16,C47,E47,G47,I47,K47,M47,O47,Q47,S47) -> 11977087 | D16: =[1]게이트볼장!E6 -> 31 | E16: =[1]게이트볼장!K6 -> 25483.5 | F16: =[1]게이트볼장!E38 -> 15 | G16: =[1]게이트볼장!K38 -> 264045.15 | H16: =[1]게이트볼장!E54 -> 13 | I16: =[1]게이트볼장!K54 -> 27110 | J16: =[1]게이트볼장!E68 -> 78 | K16: =[1]게이트볼장!K68 -> 393009.45 | L16: =[1]게이트볼장!E147 -> 45 | M16: =[1]게이트볼장!K147 -> 35019 | N16: =[1]게이트볼장!E193 -> 22 | O16: =[1]게이트볼장!K193 -> 296060.9 | P16: =[1]게이트볼장!E216 -> 27 | Q16: =[1]게이트볼장!K216 -> 168106 | R16: =[1]게이트볼장!E244 -> 14 | S16: =[1]게이트볼장!K244 -> 26439
A17: 11. 수영장 | B17: =SUM(D17,F17,H17,J17,L17,N17,P17,R17,B48,D48,F48,H48,J48,L48,N48,P48,R48) -> 579 | C17: =SUM(E17,G17,I17,K17,M17,O17,Q17,S17,C48,E48,G48,I48,K48,M48,O48,Q48,S48) -> 13272657 | D17: =[1]수영장!E6 -> 99 | E17: =[1]수영장!L6 -> 599326.11 | F17: =[1]수영장!E106 -> 28 | G17: =[1]수영장!L106 -> 381283 | H17: =[1]수영장!E135 -> 20 | I17: =[1]수영장!L135 -> 295874.8 | J17: =[1]수영장!E156 -> 28 | K17: =[1]수영장!L156 -> 1208302.2 | L17: =[1]수영장!E185 -> 10 | M17: =[1]수영장!L185 -> 108509.1 | N17: =[1]수영장!E196 -> 19 | O17: =[1]수영장!L196 -> 43770.66 | P17: =[1]수영장!E216 -> 16 | Q17: =[1]수영장!L216 -> 460601 | R17: =[1]수영장!E233 -> 7 | S17: =[1]수영장!L233 -> 17444
A18: 12. 롤러스케이트장 | B18: =SUM(D18,F18,H18,J18,L18,N18,P18,R18,B49,D49,F49,H49,J49,L49,N49,P49,R49) -> 184 | C18: =SUM(E18,G18,I18,K18,M18,O18,Q18,S18,C49,E49,G49,I49,K49,M49,O49,Q49,S49) -> 2637650.6 | D18: =[1]롤러스케이트장!D6 -> 14 | E18: =[1]롤러스케이트장!G6 -> 61954 | F18: =[1]롤러스케이트장!D21 -> 13 | G18: =[1]롤러스케이트장!G21 -> 69493 | H18: =[1]롤러스케이트장!D35 -> 6 | I18: =[1]롤러스케이트장!G35 -> 40440 | J18: =[1]롤러스케이트장!D42 -> 4 | K18: =[1]롤러스케이트장!G42 -> 40738 | L18: =[1]롤러스케이트장!D47 -> 2 | M18: =[1]롤러스케이트장!G47 -> 22542 | N18: =[1]롤러스케이트장!D50 -> 2 | O18: =[1]롤러스케이트장!G50 -> 25727.6 | P18: =[1]롤러스케이트장!D53 -> 2 | Q18: =[1]롤러스케이트장!G53 -> 18300 | R18: =[1]롤러스케이트장!D56 -> 9 | S18: =[1]롤러스케이트장!G56 -> 27016
A19: 13. 사격장 | B19: =SUM(D19,F19,H19,J19,L19,N19,P19,R19,B50,D50,F50,H50,J50,L50,N50,P50,R50) -> 26 | C19: =SUM(E19,G19,I19,K19,M19,O19,Q19,S19,C50,E50,G50,I50,K50,M50,O50,Q50,S50) -> 1083972 | F19: 1 | G19: =[1]사격장!K6 -> 6009 | H19: 1 | I19: =[1]사격장!K7 -> 191300 | J19: 1 | K19: =[1]사격장!K8 -> 95837 | P19: 1 | Q19: =[1]사격장!K9 -> 3700
A20: 14. 국궁장 | B20: =SUM(D20,F20,H20,J20,L20,N20,P20,R20,B51,D51,F51,H51,J51,L51,N51,P51,R51) -> 285 | C20: =SUM(E20,G20,I20,K20,M20,O20,Q20,S20,C51,E51,G51,I51,K51,M51,O51,Q51,S51) -> 2942923.5 | D20: =[1]국궁장!E5 -> 8 | E20: =[1]국궁장!J5 -> 38873.5 | F20: =[1]국궁장!E14 -> 3 | G20: =[1]국궁장!J14 -> 11733 | H20: =[1]국궁장!E18 -> 3 | I20: =[1]국궁장!J18 -> 21186 | J20: =[1]국궁장!E22 -> 8 | K20: =[1]국궁장!J22 -> 100241 | L20: =[1]국궁장!E31 -> 3 | M20: =[1]국궁장!J31 -> 40891 | N20: =[1]국궁장!E35 -> 5 | O20: =[1]국궁장!J35 -> 1779.56 | P20: =[1]국궁장!E41 -> 4 | Q20: =[1]국궁장!J41 -> 49699 | R20: =[1]국궁장!E46 -> 3 | S20: =[1]국궁장!J46 -> 23717
A21: 15. 양궁장 | B21: =SUM(D21,F21,H21,J21,L21,N21,P21,R21,B52,D52,F52,H52,J52,L52,N52,P52,R52) -> 28 | C21: =SUM(E21,G21,I21,K21,M21,O21,Q21,S21,C52,E52,G52,I52,K52,M52,O52,Q52,S52) -> 743211 | F21: 1 | G21: =[1]양궁장!J6 -> 20576 | H21: =[1]양궁장!E7 -> 3 | I21: =[1]양궁장!J7 -> 43059 | J21: =[1]양궁장!E11 -> 2 | K21: =[1]양궁장!J11 -> 13061 | L21: =[1]양궁장!E14 -> 1 | M21: =[1]양궁장!J14 -> 45109 | N21: 1 | O21: =[1]양궁장!J16 -> 320 | P21: 1 | Q21: =[1]양궁장!J17 -> 103117
A22: 16. 승마장 | B22: =SUM(D22,F22,H22,J22,L22,N22,P22,R22,B53,D53,F53,H53,J53,L53,N53,P53,R53) -> 24 | C22: =SUM(E22,G22,I22,K22,M22,O22,Q22,S22,C53,E53,G53,I53,K53,M53,O53,Q53,S53) -> 1065286 | F22: =[1]승마장!E6 -> 2 | G22: =[1]승마장!L6 -> 27381.12 | H22: =[1]승마장!E9 -> 3 | I22: =[1]승마장!L9 -> 37049 | L22: 1 | M22: =[1]승마장!L13 -> 26084 | N22: 1 | O22: =[1]승마장!L14 -> 5215
A23: 17. 골프연습장 | B23: =SUM(D23,F23,H23,J23,L23,N23,P23,R23,B54,D54,F54,H54,J54,L54,N54,P54,R54) -> 92 | C23: =SUM(E23,G23,I23,K23,M23,O23,Q23,S23,C54,E54,G54,I54,K54,M54,O54,Q54,S54) -> 1340909.4 | D23: =[1]골프연습장!E6 -> 33 | E23: =[1]골프연습장!J6 -> 192186 | F23: =[1]골프연습장!E40 -> 7 | G23: =[1]골프연습장!J40 -> 4942 | H23: 1 | I23: =[1]골프연습장!L48 -> 7519 | J23: =[1]골프연습장!E49 -> 4 | K23: =[1]골프연습장!J49 -> 160634 | L23: =[1]골프연습장!E54 -> 2 | M23: =[1]골프연습장!J54 -> 30626
A24: 18. 조정카누장 | B24: =SUM(D24,F24,H24,J24,L24,N24,P24,R24,B55,D55,F55,H55,J55,L55,N55,P55,R55) -> 10 | C24: =SUM(E24,G24,I24,K24,M24,O24,Q24,S24,C55,E55,G55,I55,K55,M55,O55,Q55,S55) -> 1197279 | F24: 1 | G24: =[1]조정카누장!J6 -> 25252
A25: 19. 요트장 | B25: =SUM(D25,F25,H25,J25,L25,N25,P25,R25,B56,D56,F56,H56,J56,L56,N56,P56,R56) -> 15 | C25: =SUM(E25,G25,I25,K25,M25,O25,Q25,S25,C56,E56,G56,I56,K56,M56,O56,Q56,S56) -> 315018 | F25: 1 | G25: =[1]요트장!K6 -> 138561
A26: 20. 빙상장 | B26: =SUM(D26,F26,H26,J26,L26,N26,P26,R26,B57,D57,F57,H57,J57,L57,N57,P57,R57) -> 36 | C26: =SUM(E26,G26,I26,K26,M26,O26,Q26,S26,C57,E57,G57,I57,K57,M57,O57,Q57,S57) -> 3745426.6 | D26: =[1]빙상장!E6 -> 3 | E26: =[1]빙상장!H6 -> 36540 | F26: =[1]빙상장!E10 -> 2 | G26: =[1]빙상장!H10 -> 116524 | H26: 1 | I26: =[1]빙상장!H13 -> 3693 | J26: 1 | K26: =[1]빙상장!H14 -> 441659 | L26: 1 | M26: =[1]빙상장!J15 -> 4117 | N26: 1 | O26: =[1]빙상장!H16 -> 13439 | R26: 1 | S26: =[1]빙상장!H17 -> 526468
A27: 21. 설상경기장 | B27: =SUM(D27,F27,H27,J27,L27,N27,P27,R27,B58,D58,F58,H58,J58,L58,N58,P58,R58) -> 4 | C27: =SUM(E27,G27,I27,K27,M27,O27,Q27,S27,C58,E58,G58,I58,K58,M58,O58,Q58,S58) -> 462499.9
A28: 22. 파크골프장 | B28: =SUM(D28,F28,H28,J28,L28,N28,P28,R28,B59,D59,F59,H59,J59,L59,N59,P59,R59) -> 461 | C28: =SUM(E28,G28,I28,K28,M28,O28,Q28,S28,C59,E59,G59,I59,K59,M59,O59,Q59,S59) -> 8587905.3 | D28: =[1]파크골프장!E6 -> 23 | E28: =[1]파크골프장!G6 -> 201735 | F28: =[1]파크골프장!E30 -> 17 | G28: =[1]파크골프장!G30 -> 285722.3 | H28: =[1]파크골프장!E48 -> 34 | I28: =[1]파크골프장!G48 -> 561394 | J28: =[1]파크골프장!E83 -> 4 | K28: =[1]파크골프장!G83 -> 27645 | L28: =[1]파크골프장!E88 -> 10 | M28: =[1]파크골프장!G88 -> 182238 | N28: =[1]파크골프장!E99 -> 4 | O28: =[1]파크골프장!G99 -> 99181 | P28: =[1]파크골프장!E104 -> 8 | Q28: =[1]파크골프장!G104 -> 116566 | R28: =[1]파크골프장!E113 -> 7 | S28: =[1]파크골프장!G113 -> 123234
A29: 23. 기타시설 | B29: =SUM(D29,F29,H29,J29,L29,N29,P29,R29,B60,D60,F60,H60,J60,L60,N60,P60,R60) -> 2676 | C29: =SUM(E29,G29,I29,K29,M29,O29,Q29,S29,C60,E60,G60,I60,K60,M60,O60,Q60,S60) -> 19597774 | D29: =D30+D31 -> 161 | E29: =E30+E31 -> 521755.78 | F29: =F30+F31 -> 111 | G29: =G30+G31 -> 244846.8 | H29: =H30+H31 -> 33 | I29: =I30+I31 -> 125409 | J29: =J30+J31 -> 47 | K29: =K30+K31 -> 1267698.6 | ... S29: =S30+S31 -> 48266
A30: - 풋살장 | B30: =SUM(D30,F30,H30,J30,L30,N30,P30,R30,B61,D61,F61,H61,J61,L61,N61,P61,R61) -> 630 | C30: =SUM(E30,G30,I30,K30,M30,O30,Q30,S30,C61,E61,G61,I61,K61,M61,O61,Q61,S61) -> 5382925.7 | D30: ='[1]기타 체육시설(풋살장)'!E6 -> 34 | E30: ='[1]기타 체육시설(풋살장)'!G6 -> 136980 | F30: ='[1]기타 체육시설(풋살장)'!E41 -> 9 | G30: ='[1]기타 체육시설(풋살장)'!G41 -> 38513 | H30: ='[1]기타 체육시설(풋살장)'!E51 -> 11 | I30: ='[1]기타 체육시설(풋살장)'!G51 -> 74750 | J30: ='[1]기타 체육시설(풋살장)'!E63 -> 9 | K30: ='[1]기타 체육시설(풋살장)'!G63 -> 8683 | L30: ='[1]기타 체육시설(풋살장)'!E73 -> 5 | M30: ='[1]기타 체육시설(풋살장)'!G73 -> 8104 | N30: ='[1]기타 체육시설(풋살장)'!E79 -> 5 | O30: ='[1]기타 체육시설(풋살장)'!G79 -> 46041 | P30: ='[1]기타 체육시설(풋살장)'!E85 -> 34 | Q30: ='[1]기타 체육시설(풋살장)'!G85 -> 31305 | R30: ='[1]기타 체육시설(풋살장)'!E120 -> 14 | S30: ='[1]기타 체육시설(풋살장)'!G120 -> 19434
A31: - 그외 | B31: =SUM(D31,F31,H31,J31,L31,N31,P31,R31,B62,D62,F62,H62,J62,L62,N62,P62,R62) -> 2046 | C31: =SUM(E31,G31,I31,K31,M31,O31,Q31,S31,C62,E62,G62,I62,K62,M62,O62,Q62,S62) -> 14214848 | D31: ='[1]기타 체육시설(그외)'!E6 -> 127 | E31: ='[1]기타 체육시설(그외)'!G6 -> 384775.78 | F31: ='[1]기타 체육시설(그외)'!E134 -> 102 | G31: ='[1]기타 체육시설(그외)'!G134 -> 206333.8 | H31: ='[1]기타 체육시설(그외)'!E237 -> 22 | I31: ='[1]기타 체육시설(그외)'!G237 -> 50659 | J31: ='[1]기타 체육시설(그외)'!E260 -> 38 | K31: ='[1]기타 체육시설(그외)'!G260 -> 1259015.6 | L31: ='[1]기타 체육시설(그외)'!E299 -> 25 | M31: ='[1]기타 체육시설(그외)'!G299 -> 129488 | N31: ='[1]기타 체육시설(그외)'!E325 -> 24 | O31: ='[1]기타 체육시설(그외)'!G325 -> 112946 | P31: ='[1]기타 체육시설(그외)'!E350 -> 25 | Q31: ='[1]기타 체육시설(그외)'!G350 -> 63393 | R31: ='[1]기타 체육시설(그외)'!E376 -> 20 | S31: ='[1]기타 체육시설(그외)'!G376 -> 28832
A32: 시 설 항 목 | B32: 경기 | D32: 강원 | F32: 충북 | H32: 충남 | J32: 전북 | L32: 전남 | N32: 경북 | P32: 경남 | R32: 제주
B33: 개소 | C33: 면적 | D33: 개소 | E33: 면적 | F33: 개소 | G33: 면적 | H33: 개소 | I33: 면적 | J33: 개소 | K33: 면적 | L33: 개소 | M33: 면적 | N33: 개소 | O33: 면적 | P33: 개소 | Q33: 면적 | R33: 개소 | S33: 면적
A34: 합 계 | B34: =SUM(B35:B43,B47:B60) -> 5029 | C34: =SUM(C35:C43,C47:C60) -> 58957064 | D34: =SUM(D35:D43,D47:D60) -> 3032 | E34: =SUM(E35:E43,E47:E60) -> 17936983 | F34: =SUM(F35:F43,F47:F60) -> 2735 | G34: =SUM(G35:G43,G47:G60) -> 11621210 | H34: =SUM(H35:H43,H47:H60) -> 2425 | I34: =SUM(I35:I43,I47:I60) -> 14071325 | ... S34: =SUM(S35:S43,S47:S60) -> 4356807
A35: 1. 육상경기장 | B35: =[1]육상경기장!E43 -> 40 | C35: =[1]육상경기장!L43 -> 4366820.9 | D35: =[1]육상경기장!E84 -> 33 | E35: =[1]육상경기장!L84 -> 1904302 | F35: =[1]육상경기장!E118 -> 17 | G35: =[1]육상경기장!L118 -> 1011100 | H35: =[1]육상경기장!E136 -> 17 | I35: =[1]육상경기장!L136 -> 1898359 | J35: =[1]육상경기장!E154 -> 14 | K35: =[1]육상경기장!L154 -> 1071246 | L35: =[1]육상경기장!E169 -> 29 | M35: =[1]육상경기장!L169 -> 2211107 | N35: =[1]육상경기장!E199 -> 22 | O35: =[1]육상경기장!L199 -> 1645018 | P35: =[1]육상경기장!E222 -> 32 | Q35: =[1]육상경기장!L222 -> 2588711.9 | R35: =[1]육상경기장!E255 -> 15 | S35: =[1]육상경기장!L255 -> 702374
A36: 2. 축구장 | B36: =[1]축구장!E274 -> 279 | C36: =[1]축구장!I274 -> 9332549.5 | D36: =[1]축구장!E554 -> 76 | E36: =[1]축구장!I554 -> 1883699 | F36: =[1]축구장!E631 -> 43 | G36: =[1]축구장!I631 -> 1452397 | H36: =[1]축구장!E675 -> 41 | I36: =[1]축구장!I631 -> 1452397 | J36: =[1]축구장!E717 -> 97 | K36: =[1]축구장!I717 -> 3241934 | L36: =[1]축구장!E815 -> 92 | M36: =[1]축구장!I815 -> 3019174 | N36: =[1]축구장!E908 -> 78 | O36: =[1]축구장!I908 -> 2363609 | P36: =[1]축구장!E987 -> 175 | Q36: =[1]축구장!I987 -> 4237781.1 | R36: =[1]축구장!E1163 -> 22 | S36: =[1]축구장!I1163 -> 830328
A37: 3. 하키장 | B37: =[1]하키장!E15 -> 3 | C37: =[1]하키장!J15 -> 44017 | D37: =[1]하키장!E19 -> 2 | E37: =[1]하키장!J19 -> 38157 | F37: =[1]하키장!E22 -> 2 | G37: =[1]하키장!J22 -> 43662 | H37: =[1]하키장!E25 -> 1 | I37: =[1]하키장!J25 -> 14063 | J37: =[1]하키장!E27 -> 2 | K37: =[1]하키장!J27 -> 266289 | L37: =[1]하키장!E30 -> 2 | M37: =[1]하키장!J30 -> 221560 | P37: =[1]하키장!E33 -> 1 | Q37: =[1]하키장!J33 -> 32725
A38: 4. 야구장 | B38: =[1]야구장!E103 -> 81 | C38: =[1]야구장!J103 -> 1845960.6 | D38: =[1]야구장!E185 -> 27 | E38: =[1]야구장!J185 -> 820332 | F38: =[1]야구장!E219 -> 17 | G38: =[1]야구장!J219 -> 1466345.4 | H38: =[1]야구장!E237 -> 26 | I38: =[1]야구장!J237 -> 591066 | J38: =[1]야구장!E264 -> 24 | K38: =[1]야구장!J264 -> 523721 | L38: =[1]야구장!E289 -> 31 | M38: =[1]야구장!J289 -> 1222569 | N38: =[1]야구장!E321 -> 32 | O38: =[1]야구장!J321 -> 987123 | P38: =[1]야구장!E356 -> 38 | Q38: =[1]야구장!J356 -> 999287 | R38: =[1]야구장!E395 -> 8 | S38: =[1]야구장!J395 -> 234659
A39: 5. 싸이클경기장 | B39: 1 | C39: =[1]싸이클경기장!L11 -> 25456 | D39: 1 | E39: =[1]싸이클경기장!L12 -> 82346 | F39: 1 | G39: =[1]싸이클경기장!L13 -> 64948 | J39: 1 | K39: =[1]싸이클경기장!L14 -> 33013 | L39: 1 | M39: =[1]싸이클경기장!L15 -> 28017 | P39: 1 | Q39: =[1]싸이클경기장!L16 -> 54396
A40: 6. 테니스장 | B40: =[1]테니스장!E257 -> 230 | C40: =[1]테니스장!K257 -> 2279138.2 | D40: =[1]테니스장!E488 -> 78 | E40: =[1]테니스장!K488 -> 993320.9 | F40: =[1]테니스장!E567 -> 35 | G40: =[1]테니스장!K567 -> 701432.56 | H40: =[1]테니스장!E603 -> 46 | I40: =[1]테니스장!K603 -> 611458.71 | J40: =[1]테니스장!E650 -> 55 | K40: =[1]테니스장!K650 -> 1459258 | L40: =[1]테니스장!E706 -> 51 | M40: =[1]테니스장!K706 -> 658536.78 | N40: =[1]테니스장!E758 -> 67 | O40: =[1]테니스장!K758 -> 807671.2 | P40: =[1]테니스장!E826 -> 101 | Q40: =[1]테니스장!K826 -> 1045879.6 | R40: =[1]테니스장!E928 -> 8 | S40: =[1]테니스장!K928 -> 53999
...

Sheet 1.육상경기장
B1: 1. 육상경기장 | AI1: (단위 : ㎡, 백만원, 명)
A2: 일련번호 | B2: 시도 | C2: 시군구 | D2: 주소 | E2: 시설명 | F2: 소유기관 | G2: 운영조직 (연락처) | I2: 관리주체 | J2: 관리인원 | K2: 이용단체명 | L2: 부지면적 | M2: 건축면적 | N2: 연면적 | O2: 경기장 | W2: 관람석 | AA2: 국제규격 (O,X) | AB2: 준공 연도 | AC2: 건 설 사업비 | AJ2: 개보수연도 | AL2: 부대시설 | AR2: 부대운동시설 | BL2: 비고
H3: 홈페이지주소 | O3: 트랙 | T3: 필드 | W3: 좌석수 | X3: 수용인원 | Y3: 좌석형태 | Z3: 건축구조 | AJ3: 1차 | AK3: 2차 | AL3: 전광판 | AN3: 조명탑 | AQ3: 기타 | AR3: 종목1 | AW3: 종목2 | BB3: 종목3 | BG3: 종목4
O4: 바닥재료 | P4: 주로연장 | Q4: 주로폭(m) | R4: 주로수 | S4: 주로면적(㎡) | T4: 바닥재료 | U4: 폭(m) | V4: 길이(m) | AL4: 개소수 | AM4: 설치비 | AN4: 개소수 | AO4: 조도 | AP4: 설치비 | AR4: 종목 | AS4: 면수 | AT4: 면적 | AU4: 시설구성 | AV4: 관리운영 | AW4: 종목 | AX4: 면수 | AY4: 면적 | AZ4: 시설구성 | BA4: 관리운영 | BB4: 종목 | BC4: 면수 | BD4: 면적 | BE4: 시설구성 | BF4: 관리운영 | BG4: 종목 | BH4: 면수 | BI4: 면적 | BJ4: 시설구성 | BK4: 관리운영
B5: 전국 | C5: 계 | E5: =COUNTA(E7:E9,E11:E13,E15:E19,E21:E30,E32:E33,E35:E40,E42,E44:E83,E85:E117,E119:E135,E137:E153,E155:E168,E170:E198,E200:E221,E223:E254,E256:E270) -> 249 | G5: =COUNTA(G7:G9,G11:G13,G15:G19,G21:G30,G32:G33,G35:G40,G42,G44:G83,G85:G117,G119:G135,G137:G153,G155:G168,G170:G198,G200:G221,G223:G253,G255:G269) -> 193 | H5: =COUNTA(H7:H9,H11:H13,H15:H19,H21:H30,H32:H33,H35:H40,H42,H44:H83,H85:H117,H119:H135,H137:H153,H155:H168,H170:H198,H200:H221,H223:H253,H255:H269) -> 85 | J5: =COUNTA(J7:J9,J11:J13,J15:J19,J21:J30,J32:J33,J35:J40,J42,J44:J83,J85:J117,J119:J135,J137:J153,J155:J168,J170:J198,J200:J221,J223:J253,J255:J269) -> 148 | K5: =COUNTA(K7:K9,K11:K13,K15:K19,K21:K30,K32:K33,K35:K40,K42,K44:K83,K85:K117,K119:K135,K137:K153,K155:K168,K170:K198,K200:K221,K223:K253,K255:K269) -> 106 | L5: =SUM(L7:L9,L11:L13,L15:L19,L21:L30,L32:L33,L35:L40,L42,L44:L83,L85:L117,L119:L135,L137:L153,L155:L168,L170:L198,L200:L221,L223:L254,L256:L270) -> 20596790 | M5: =SUM(M7:M9,M11:M13,M15:M19,M21:M30,M32:M33,M35:M40,M42,M44:M83,M85:M117,M119:M135,M137:M153,M155:M168,M170:M198,M200:M221,M223:M254,M256:M270) -> 1692451.8 | N5: =SUM(N7:N9,N11:N13,N15:N19,N21:N30,N32:N33,N35:N40,N42,N44:N83,N85:N117,N119:N135,N137:N153,N155:N168,N170:N198,N200:N221,N223:N254,N256:N270) -> 2492971.1
B6: 서울 | C6: 소 계 | E6: =COUNTA(E7:E9) -> 3 | L6: =SUM(L7:L9) -> 249613 | M6: =SUM(M7:M9) -> 41874 | N6: =SUM(N7:N9) -> 124334
A7: 1 | C7: 양천구 | D7: 안양천길336 | E7: 목동운동장 | F7: 서울시 | G7: 서울시시설관리사업소 | H7: stadium.seoul.go.kr | I7: 체육시설관리사업소 | J7: 26 | L7: 49327 | M7: 5860 | N7: 22124 | O7: 우레탄 | P7: 400 | R7: 8 | T7: 인조잔디 | U7: 105 | V7: 68 | W7: 20236 | X7: 30000 | Y7: 의자식 | Z7: 철근콘크리트 | AB7: 1989 | AC7: 8111 | AI7: 8111 | AJ7: 1987-1989 | AL7: 전광판 | AN7: 조명탑수
A8: 2 | C8: 송파구 | D8: 잠실동10번지 | E8: 잠실주경기장 | F8: 서울시 | G8: 서울시시설관리사업소 | H8: stadium.seoul.go.kr | I8: 체육시설관리사업소 | J8: 7 | K8: 축구,육상,행사 | L8: 179386 | M8: 33957 | N8: 100151 | O8: 우레탄 | P8: 400 | R8: 8 | T8: 천연잔디 | U8: 105 | V8: 70 | W8: 69599 | X8: 100000 | Y8: 의자식 | Z8: 철근콘크리트 | AB8: 1984 | AC8: 47962 | AE8: 10002 | AI8: 47962 | AJ8: 1977-1984 | AL8: 전광판 | AN8: 조명탑 | BL8: 리모델링 공사 착공으로 운영 중단 및 2026년 12월경 재개관 예정
A9: 3 | C9: 송파구 | D9: 잠실동10번지 | E9: 잠실보조경기장 | F9: 서울시 | G9: 서울시시설관리사업소 | H9: stadium.seoul.go.kr | I9: 체육시설관리사업소 | J9: 2 | K9: 육상,행사 | L9: 20900 | M9: 2057 | N9: 2059 | O9: 우레탄 | P9: 400 | R9: 8 | T9: 천연잔디 | U9: 105 | V9: 68 | W9: 1809 | X9: 4000 | Y9: 계단식 | Z9: 철근콘크리트 | AB9: 1984 | AI9: 주경기장에 포함 | AJ9: 1977-1984 | AN9: 조명탑 | BL9: 리모델링 공사 착공으로 운영 중단 및 2026년 12월경 재개관 예정
B10: 부산 | C10: 소 계 | E10: =COUNTA(E11:E13) -> 3 | L10: =SUM(L11:L13) -> 144597 | M10: =SUM(M11:M13) -> 67787 | N10: =SUM(N11:N13) -> 107462
A11: 1 | C11: 연제구 | D11: 거제2동 1300 | E11: 부산아시아드 주경기장 | F11: 부산시 | G11: 체육시설관리사업소 종합운동장 (051-504-8001) | H11: www.stadium.busan.kr | I11: 체육시설관리사업소 | J11: 119 | K11: 부산아이콘스 | L11: 89055 | M11: 54930 | N11: 92707 | O11: 우레탄 | P11: 400 | Q11: 1.2 | R11: 8 | T11: 천연잔디 | U11: 75.28 | V11: 109 | W11: 53769 | X11: 80000 | Y11: 의자식 | Z11: 철근콘크리트 | AB11: 2001 | AD11: 158948 | AE11: 68000 | AI11: 226948 | AL11: 2(20.48＊8.96) | AM11: 6170 | AN11: 2 | AO11: 3096 | AP11: 528 | AQ11: 탈의실, 샤워실, 매점
A12: 2 | C12: 연제구 | D12: 거제2동 1300 | E12: 부산아시아드 보조경기장 | F12: 부산시 | G12: 체육시설관리사업소 종합운동장 (051-504-8001) | H12: www.stadium.busan.kr | I12: 체육시설관리사업소 | K12: 부산아이콘스 | L12: 25043 | M12: 0 | N12: 1408 | O12: 우레탄 | P12: 400 | Q12: 1.2 | R12: 8 | T12: 천연잔디 | U12: 75.28 | V12: 109 | W12: 4549 | X12: 15000 | Y12: 의자식 | Z12: 철근콘크리트 | AB12: 2001 | AI12: 주경기장에 포함 | AN12: 2 | AO12: 2000 | AP12: 196
A13: 3 | C13: 서구 | E13: 구덕종합운동장 주경기장 | F13: 부산시 | G13: 체육시설관리사업소 구덕운동장 (051-247-5771) | H13: www.stadium.busan.kr | I13: 체육시설관리사업소 | J13: 35 | L13: 30499 | M13: 12857 | N13: 13347 | O13: 우레탄 | P13: 400 | R13: 8 | T13: 천연잔디 | U13: 72 | V13: 109 | W13: 12349 | X13: 12349 | Y13: 의자식 | Z13: 철근콘크리트 | AB13: 1973 | AD13: 5888 | AI13: 1828 | AJ13: 2000 | AK13: 2001 | AL13: 1(20.31＊8.13) | AM13: 2823 | AN13: 5 | AO13: 1400 | AP13: 경기장 건립시 설치 | AR13: 넓이뛰기 | AS13: 1 | AW13: 투포환 | AX13: 1
B14: 대구 | C14: 소 계 | E14: =COUNTA(E15:E19) -> 5 | L14: =SUM(L15:L19) -> 708147 | M14: =SUM(M15:M19) -> 89737 | N14: =SUM(N15:N19) -> 163425
A15: 1 | C15: 동 구 | E15: 율하체육공원 운동장 | F15: 대구시 | I15: 동구 체육진흥과 (직영) | L15: 24128 | O15: 우레탄 | P15: 400 | R15: 8 | T15: 인조잔디 | U15: 68 | V15: 105 | W15: 880 | X15: 990 | AB15: 2009 | AI15: 1373
C16: 수성구 | D16: 대흥동 504 | E16: 대구스타디움 | F16: 대구시 | G16: 대구시체육시설관리사무소 | H16: http://sports.daegu.go.kr | I16: 체육시설관리부 | J16: 45 | K16: 대구FC프로축구팀 | L16: 467779 | M16: 45939 | N16: 140995 | O16: 롤시트 | P16: 400 | R16: 8 | T16: 천연잔디 | U16: 72 | V16: 109 | W16: 66422 | X16: 100000 | Y16: 의자식 | Z16: 철근콘크리트 | AB16: 2001 | AD16: 211,490백만원 | AE16: 72,110백만원 | AI16: 283600 | BL16: 바닥재 변경
C17: 수성구 | E17: 대구스타디움 보조경기장 | F17: 대구시 | I17: 체육시설관리부 | L17: 44700 | M17: 1467 | N17: 853 | O17: 롤시트 | P17: 400 | R17: 8 | T17: 천연잔디 | U17: 72 | V17: 109 | W17: 2500 | X17: 3000 | AB17: 2001 | AI17: 주경기장에 포함 | AL17: 1 | AM17: 7,100백만원 | AN17: 1 | AO17: 1,800∼2,200lux | BL17: 바닥재 변경
A18: 2 | C18: 달성군 | E18: 달성종합스포츠파크 주경기장 | F18: 달성군 | I18: 달성군시설관리공단 | L18: 144500 | M18: 28900 | O18: 우레탄 | P18: 400 | R18: 8 | T18: 인조잔디 | U18: 65 | V18: 105 | W18: 8758 | AB18: 2014 | AI18: 53600
C19: 수성구 | E19: 육상진흥센터 | F19: 대구시 | I19: 체육시설관리부 | L19: 27040 | M19: 13431 | N19: 21577 | O19: 우레탄 | P19: 200 | R19: 6 | T19: 우레탄 | U19: 34 | V19: 79 | W19: 5000 | X19: 7500 | AB19: 2013 | AI19: 72451
B20: 인천 | C20: 소 계 | E20: =COUNTA(E21:E30) -> 10 | L20: =SUM(L21:L30) -> 1305232 | M20: =SUM(M21:M30) -> 114543.55 | N20: =SUM(N21:N30) -> 215683.07
A21: 1 | C21: 미추홀구 | E21: 문학경기장 | F21: 인천시 | I21: 주식회사 신세계야구단 | L21: 432035 | M21: 34355 | N21: 95226 | O21: 우레탄 | P21: 400 | R21: 8 | S21: 330518 | T21: 천연잔디 | U21: 71 | V21: 106 | W21: 49084 | X21: 50500 | Y21: 50256 | Z21: 의자식 | AB21: 2002 | AC21: 2002 | AE21: 47400 | AG21: 41800 | AH21: 36000 | AI21: 330518 | AJ21: 125200 | AM21: 1 | AN21: 5500 | AO21: 2 | AP21: 2300lux | AQ21: 4600 | AS21: 인공암장 | AU21: 102.49 | AW21: 유스센터
C22: 미추홀구 | E22: 문학보조경기장 | F22: 인천시 | I22: 주식회사 신세계야구단 | M22: 1009 | N22: 1539 | O22: 우레탄 | P22: 400 | R22: 8 | S22: 주경기장에 포함 | T22: 천연잔디 | U22: 71 | V22: 106 | X22: 5000 | AB22: 2002 | AI22: 주경기장에 포함
C23: 서구 | D23: 연희동 봉수대로 806 | E23: 인천아시아드주경기장 | F23: 인천시 | G23: 인천시설공단(032-456-2100) | I23: 인천시설공단 | J23: 44 | L23: 631975 | M23: 74102 | N23: 113470 | O23: 우레탄 | P23: 400 | R23: 8 | S23: 467200 | T23: 천연잔디 | U23: 68 | V23: 105 | W23: 29376 | AB23: 2014 | AI23: 467200
C24: 서구 | D24: 연희동 봉수대로 806 | E24: 인천아시아드 보조경기장 | F24: 인천시 | G24: 인천시설공단(032-456-2100) | I24: 인천시설공단 | J24: 44 | N24: 193 | O24: 우레탄 | P24: 400 | R24: 8 | T24: 천연잔디 | U24: 68 | V24: 105 | W24: 5034 | AB24: 2014 | BL24: 주 경기장에 포함
C25: 옹진군 | E25: 북도면 종합운동장 | F25: 옹진군 | I25: 옹진군 | L25: 27910 | M25: 632.55 | N25: 809.71 | O25: 우레탄 | S25: 4199 | T25: 인조잔디 | U25: 68 | V25: 105 | W25: 900 | X25: 900 | AB25: 2009 | AI25: 4199 | BL25: 육상트랙, 축구장, 족구장, 게이트볼장, 다목적구장
C26: 옹진군 | E26: 연평면 종합운동장 | F26: 옹진군 | I26: 옹진군 | L26: 16359 | M26: 849 | N26: 849 | O26: 우레탄 | S26: 3050 | T26: 인조잔디 | U26: 64 | V26: 100 | W26: 840 | X26: 840 | AB26: 2010 | AI26: 3050 | BL26: 육상트랙, 축구장, 농구장, 다목적구장
C27: 옹진군 | E27: 백령면 종합운동장 | F27: 옹진군 | I27: 옹진군 | L27: 37388 | M27: 867 | N27: 867.36 | O27: 우레탄 | P27: 400 | R27: 7 | S27: 3464 | T27: 인조잔디 | U27: 56 | V27: 120 | W27: 900 | X27: 900 | AB27: 2010 | AI27: 3464 | BL27: 육상트랙, 축구장, 농구장, 씨름장, 다목적구장
C28: 옹진군 | E28: 대청면 답동 종합운동장 | F28: 옹진군 | I28: 옹진군 | L28: 12018 | M28: 592 | N28: 592 | O28: 우레탄 | P28: 400 | R28: 3 | S28: 2442 | T28: 인조잔디 | U28: 56 | V28: 120 | W28: 810 | X28: 810 | Y28: 5000 | AB28: 2012 | AC28: 2002 | AI28: 2442 | AJ28: 주경기장에포함 | BL28: 육상트랙, 축구장, 농구장, 다목적구장
C29: 옹진군 | E29: 덕적면 종합운동장 | F29: 옹진군 | I29: 옹진군 | L29: 17000 | M29: 922 | N29: 922 | O29: 우레탄 | S29: 2510 | T29: 인조잔디 | U29: 65 | V29: 100 | W29: 950 | X29: 950 | AB29: 2011 | AI29: 2510 | BL29: 육상트랙, 축구장, 테니스장, 족구장
C30: 옹진군 | E30: 영흥면 종합운동장 | F30: 옹진군 | I30: 옹진군 | L30: 130547 | M30: 1215 | N30: 1215 | O30: 우레탄 | S30: 7900 | T30: 인조잔디 | U30: 68 | V30: 105 | W30: 1100 | X30: 1100 | AB30: 2013 | AI30: 7900 | BL30: 육상트랙, 축구장, 테니스장, 다목적구장
B31: 광주 | C31: 소 계 | E31: =COUNTA(E32:E33) -> 2 | L31: =SUM(L32:L33) -> 470278 | M31: =SUM(M32:M33) -> 20509.51 | N31: =SUM(N32:N33) -> 69664.3
C32: 서구 | D32: 서구 금화로 278 | E32: 광주월드컵경기장 주경기장 | F32: 광주시 | G32: 광주시체육회(062-604-2614) | I32: 위탁 (광주시체육회) | L32: 470278 | M32: 20509.51 | N32: 69459.3 | O32: 우레탄 | P32: 400 | Q32: 8 | R32: 8 | S32: 68 | T32: 천연잔디 | U32: 68 | V32: 105 | W32: 39655 | X32: 39655 | Y32: 2002 | Z32: 158788 | AB32: 2002 | AI32: 158788
C33: 서구 | D33: 서구 금화로 278 | E33: 광주월드컵경기장 보조경기장 | F33: 광주시 | G33: 광주시민프로축구단(062-373-7733) | I33: 위탁 (광주시민프로축구단) | L33: 주경기장에 포함 | M33: 주경기장포함 | N33: 205 | O33: 우레탄 | P33: 400 | Q33: 8 | R33: 8 | T33: 천연잔디 | U33: 68 | V33: 105 | W33: 831 | X33: 831 | AB33: 2002 | AI33: 주경기장에 포함 | BL33: 부지, 건축면적은 주경기장에 포함
B34: 울산 | C34: 소 계 | E34: =COUNTA(E35:E40) -> 6 | L34: =SUM(L35:L40) -> 319484 | M34: =SUM(M35:M40) -> 23941 | N34: =SUM(N35:N40) -> 38771
A35: 1 | C35: 중구 | D35: 중구 염포로 55 | E35: 울산종합운동장 | F35: 울산시 | G35: 울산시설공단(052-290-7200) | I35: 울산시설공단 | J35: 36 | L35: 113602 | M35: 22506 | N35: 37120 | O35: 우레탄 | P35: 400 | R35: 8 | T35: 천연잔디 | U35: 75 | V35: 105 | W35: 19431 | X35: 19431 | AA35: O | AB35: 2005 | AC35: 75590 | AI35: 75590 | AL35: 1(30.6m×13.14m) | AM35: 1,988백만 | AN35: 1 | AO35: 2,500LUX | AP35: 경기장 건립시 설치 | BL35: 축구장포함
C36: 중구 | D36: 중구 염포로 55 | E36: 울산종합운동장 보조조경기장 | F36: 울산시 | G36: 울산시설공단(052-290-7200) | I36: 울산시설공단 | J36: 36 | L36: 주경기장에포함 | M36: 690 | N36: 690 | O36: 우레탄 | P36: 400 | R36: 4 | T36: 인조잔디 | U36: 68 | V36: 115 | W36: 994 | X36: 994 | AB36: 2005 | AI36: 주경기장에 포함 | AN36: 1 | AO36: 1,000LUX | AP36: 경기장 건립시 설치 | BL36: 부지면적은 주경기장에 포함(축구장포함)
C37: 북구 | D37: 북구 호수중앙로 14 | E37: 농소운동장 | F37: 북구 | H37: bukgu.ulsan.kr | I37: 북구시설관리공단 | J37: 4 | L37: 44131 | M37: 68 | N37: 68 | O37: 우레탄 | P37: 400 | Q37: 1.2 | R37: 8 | S37: 4613 | T37: 인조잔디 | U37: 68 | V37: 105 | W37: 1350 | X37: 1350 | Y37: 원목 | Z37: 원목 | AB37: 2002 | AC37: 998 | AD37: 2983 | AE37: 300 | AF37: 0 | AG37: 0 | AH37: 0 | AI37: 4281 | BL37: 축구장포함
C38: 북구 | D38: 북구 농서로 301 | E38: 달천운동장 | F38: 북구 | I38: 북구시설관리공단 | L38: 21126 | M38: 90 | N38: 90 | O38: 우레탄 | P38: 370 | R38: 3 | T38: 인조잔디 | U38: 64 | V38: 105 | W38: 550 | X38: 550 | AB38: 2010 | AI38: 6323 | BL38: 축구장, 육상트랙, 인라인 스케이트장, 다목적구장 등
C39: 울주군 | D39: 울주군 노석골길 96 | E39: 간절곶스포츠파크운동장 | F39: 울주군 | G39: 울주군시설관리공단(052-229-9800) | I39: 울주군시설관리공단 | L39: 83544 | M39: 587 | N39: 668 | O39: 우레탄 | P39: 400 | R39: 8 | T39: 천연잔디 인조잔디 | U39: 68 64 | V39: 105 100 | W39: 4890 | X39: 4890 | AB39: 2007 | AI39: 21260 | BL39: 축구장 3면, 풋살경기장 1면, 육상트랙
C40: 울주군 | D40: 울주군 외고산옹기길 154 | E40: 온양체육공원운동장 | F40: 울주군 | G40: 울주군시설관리공단(052-229-9820) | I40: 울주군시설관리공단 | L40: 57081 | M40: 0 | N40: 135 | O40: 우레탄 | P40: 400 | R40: 4 | T40: 인조잔디 | U40: 67 | V40: 107 | W40: 0 | X40: 1500 | AB40: 2009 | AI40: 9798 | BL40: 축구장 1면, 풋살경기장 1면, 족구장 2면, 농구장, 육상트랙
...

Sheet 2.축구장
B1: 2. 축구장 | V1: (단위 : ㎡, 백만원, 명)
A2: 일련번호 | B2: 시도 | C2: 시군구 | D2: 주소 | E2: 시설명 | F2: 소유기관 | G2: 관리주체 | H2: 관리인원 | I2: 부지면적 | J2: 건축면적 | K2: 연면적 | L2: 경기장 | Q2: 관람석 | U2: 국제규격 (O,X) | V2: 준공 연도 | W2: 건 설 사업비 | AD2: 개보수연도 | AF2: 부대시설 | AL2: 부대운동시설 | AV2: 비고
L3: 필드 | Q3: 좌석수 | R3: 수용인원 | S3: 좌석형태 | T3: 건축구조 | AD3: 1차 | AE3: 2차 | AF3: 전광판 | AH3: 조명탑 | AK3: 기타 | AL3: 종목1 | AQ3: 종목2
L4: 바닥재료 | M4: 폭 | N4: 길이 | O4: 면적 | P4: 면수 | AF4: 개소수 | AG4: 설치비 | AH4: 개소수 | AI4: 조도 | AJ4: 설치비 | AL4: 종목 | AM4: 면수 | AN4: 면적 | AO4: 시설구성 | AP4: 관리운영 | AQ4: 종목 | AR4: 면수 | AS4: 면적 | AT4: 시설구성 | AU4: 관리운영
B5: 전국 | C5: 계 | E5: =COUNTA(E7:E80,E82:E114,E116:E154,E156:E189,E191:E215,E217:E230,E232:E259,E261:E273,E275:E553,E555:E630,E632:E674,E676:E716,E718:E814,E816:E907,E909:E986,E988:E1162,E1164:E1185) -> 1163 | H5: =COUNTA(H7:H75,H82:H112,H116:H152,H156:H188,H191:H214,H217:H230,H232:H257,H261:H273,H275:H553,H555:H630,H632:H674,H676:H716,H718:H814,H816:H907,H909:H986,H988:H1162,H1164:H1185) -> 271 | I5: =SUM(I7:I80,I82:I114,I116:I154,I156:I189,I191:I215,I217:I230,I232:I259,I261:I273,I275:I553,I555:I630,I632:I674,I676:I716,I718:I814,I816:I907,I909:I986,I988:I1162,I1164:I1185) -> 33891078 | J5: =SUM(J7:J80,J82:J114,J116:J154,J156:J189,J191:J215,J217:J230,J232:J259,J261:J273,J275:J553,J555:J630,J632:J674,J676:J716,J718:J814,J816:J907,J909:J986,J988:J1162,J1164:J1185) -> 1052885.1 | K5: =SUM(K7:K80,K82:K114,K116:K154,K156:K189,K191:K215,K217:K230,K232:K259,K261:K273,K275:K553,K555:K630,K632:K674,K676:K716,K718:K814,K816:K907,K909:K986,K988:K1162,K1164:K1185) -> 1874658.7 | P5: =P6+P81+P115+P155+P190+P216+P231+P260+P274+P554+P631+P675+P717+P815+P908+P987+P1163 -> 1376
B6: 서울 | C6: 소 계 | E6: =COUNTA(E7:E80) -> 74 | I6: =SUM(I7:I80) -> 926990 | J6: =SUM(J7:J80) -> 73298.3 | K6: =SUM(K7:K80) -> 205126.19 | P6: =SUM(P7:P80) -> 81
A7: 1 | C7: 종로구 | D7: 경기도 고양시 덕양구 덕은동 519-17 | E7: 종로구 한강다목적운동장 | F7: 국토해양부 (국유지) | G7: 종로구시설관리공단 | H7: 19790 | I7: 19790 | L7: 천연잔디 | M7: 90 74 | N7: 62 50 | O7: 6,284 4,266 | P7: 2 | Q7: 120 | R7: 120 | S7: 계단식(3단) | T7: 철제 | V7: 2013 | AB7: 920 | AV7: 한강둔치(고양시)
A8: 2 | C8: 중 구 | E8: 손기정체육공원 인조잔디축구장 | F8: 중구 | G8: 중구 시설관리공단 | H8: 18968 | I8: 3456 | L8: 인조잔디 | M8: 48 | N8: 72 | O8: 3456 | P8: 1 | S8: 계단식 | V8: 2003 | AB8: 500
A9: 3 | C9: 용산구 | D9: 효창동3번지 | E9: 효창운동장 | F9: 서울시 | G9: 체육시설관리사업소 | H9: 29976 | I9: 33391 | J9: 1802 | K9: 3414.1 | L9: 인조잔디 | M9: 105 | N9: 69 | O9: 14361 | P9: 1 | Q9: 15000 | R9: 15000 | S9: 의자식 | T9: 철근콘크리트 | V9: 1960 | AB9: 885 | AC9: 885 | AE9: 전광판 | AG9: 조명탑
C10: 용산구 | E10: 한강공원 이촌지구 축구장1 | F10: 서울시 | G10: 미래한강본부 | H10: 7350 | L10: 토사 | M10: 70 | N10: 80 | O10: 5600 | P10: 1 | S10: - | T10: - | V10: 1988 | AB10: 121
C11: 용산구 | E11: 한강공원 이촌 축구교육장 | F11: 서울시 | G11: 미래한강본부 | H11: 4534 | I11: 5283 | L11: 인조잔디 | O11: 2951 | P11: 4 | V11: 1997
C12: 성동구 | E12: 살곶이체육공원 축구장 | F12: 국토해양부 (국유지) | G12: 성동구도시관리공단 | H12: 9500 | L12: 토사 | M12: 50 | N12: 95 | O12: 9500 | P12: 2 | V12: 미상
C13: 성동구 | D13: 자동차시장3길 64 | E13: 중랑물재생센터 축구장 | F13: 서울시 | G13: 중랑물재생센터 | H13: 3600 | L13: 인조잔디 | M13: 40 | N13: 90 | O13: 3600 | P13: 1 | V13: 2017
C14: 성동구 | E14: 응봉축구장 | F14: 성동구 | G14: 성동구도시관리공단 | H14: 5154 | I14: 5154 | L14: 인조잔디 | M14: 50 | N14: 90 | O14: 5154 | P14: 1 | V14: 2017 | AB14: 800
C15: 광진구 | D15: 서울시 광진구 능동 18 | E15: 어린이대공원 축구장 | F15: 서울시 | G15: 서울시설공단 | H15: 10800 | I15: 8212 | L15: 인조잔디 | M15: 68 | N15: 100 | O15: 6834 | P15: 1 | Q15: 2000 | R15: 2000 | S15: 계단식 | T15: 콘크리트조 | V15: 2009 (2023) | AV15: 인조잔디축구장으로 변경조성(2023년/후원)
C16: 광진구 | D16: 광진구 천호대로 731 | E16: 아차산배수지체육공원 축구장 | F16: 서울시 | G16: 광진구시설관리공단 | H16: 5600 | L16: 인조잔디 | M16: 56 | N16: 100 | O16: 5600 | P16: 1 | V16: 2007 | AB16: 800
C17: 광진구 | E17: 한강공원 뚝섬지구 축구장 | F17: 서울시 | G17: 미래한강본부 | H17: 9900 | L17: 토사 | M17: 55 | N17: 90 | O17: 9900 | P17: 2 | V17: 2009
A18: 3 | C18: 중랑구 | D18: 중랑구망우동산73-2 | E18: 중랑구립 잔디운동장 | F18: 중랑구 | G18: 중랑구시설관리공단 | H18: 13304 | I18: 13304 | L18: 인조잔디 | M18: 68 | N18: 105 | O18: 9953 | P18: 1 | Q18: 400 | R18: 400 | S18: 계단식 | T18: 철제 | V18: 2002 | W18: 2,989백만원 | Y18: 560백만원 | AB18: 5568 | AC18: 5568
A19: 4 | C19: 중랑구 | D19: 중랑구 면목동 산1-4 | E19: 용마폭포공원 인조잔디 축구장 | F19: 중랑구 | G19: 중랑구시설관리공단 | H19: 8547 | I19: 8547 | L19: 인조잔디 | M19: 68 | N19: 105 | O19: 8547 | P19: 1 | Q19: 200 | R19: 200 | S19: 계단식 | T19: 철제 | V19: 2007 | AB19: 1663 | AC19: 1663
C20: 중랑구 | D20: 중랑구 망우동 4 | E20: 신내차량기지 축구장 | F20: 서울교통공사 | G20: 중랑구시설관리공단 | H20: 8186 | I20: 8186 | L20: 인조잔디 | M20: 67 | N20: 100 | O20: 8186 | P20: 1 | Q20: 100 | R20: 100 | S20: 계단식 | T20: 철제 | V20: 2017 | AB20: 878 | AC20: 878
A21: 6 | C21: 성북구 | D21: 화랑로13길 144 | E21: 제1월곡인조잔디구장 | F21: 성북구 | G21: 성북구도시관리공단 | H21: 4232 | I21: 8198 | J21: 132.3 | K21: 216.09 | L21: 인조잔디 | M21: 54 | N21: 100 | O21: 5400 | P21: 1 | S21: - | T21: - | V21: 2004 | AV21: 연면적 - 관리동
C22: 성북구 | E22: 제2월곡인조잔디구장 | F22: 성북구 | G22: 성북구도시관리공단 | I22: 6255 | J22: 1999 | K22: 1999 | L22: 인조잔디 | M22: 42 | N22: 84 | O22: 3528 | P22: 1 | S22: - | T22: - | V22: 2019
A23: 7 | C23: 성북구 | D23: 화랑로13길 144 | E23: 개운산인조잔디구장 | F23: 성북구 | G23: 성북구도시관리공단 | H23: 4232 | I23: 5000 | L23: 인조잔디 | M23: 40 | N23: 74 | O23: 2960 | P23: 1 | S23: - | T23: - | V23: 2023 | AV23: 신규
C24: 강북구 | D24: 강북구 번동 317 | E24: 강북구민운동장 | F24: 강북구 | G24: 강북구도시관리공단 | H24: 33027 | I24: 12000 | L24: 인조잔디 | M24: 68 | N24: 110 | O24: 7480 | P24: 1 | Q24: 3000 | R24: 3000 | S24: 계단식 | T24: 철근콘크리트 | V24: 2000 | AB24: 13593 | AC24: 13593
C25: 도봉구 | D25: 해등로 3길 48-11 | E25: 초안산 인조잔디축구장 | F25: 도봉구 | G25: 도봉구 시설관리공단 | H25: 6528 | I25: 6528 | L25: 인조잔디 | M25: 102 | N25: 64 | O25: 6528 | P25: 1 | V25: 2005
C26: 도봉구 | D26: 창포원로 45 다락원체육공원 | E26: 다락원체육공원 축구장 | F26: 서울시 | G26: 도봉구 시설관리공단 | H26: 49830 | I26: 8850 | L26: 인조잔디 | M26: 68 | N26: 105 | O26: 7140 | P26: 1 | S26: 계단식 | T26: 철골조 | V26: 2018
C27: 노원구 | D27: 상계동 770-2 | E27: 마들스포츠타운 축구장 | F27: 노원구 | G27: 노원구서비스공단 | H27: 8436 | I27: 8436 | L27: 인조잔디 | M27: 78 | N27: 109 | O27: 8436 | P27: 1 | Q27: 500 | R27: 500 | S27: - | T27: - | V27: 2008 | AB27: 21100
C28: 노원구 | D28: 월계동 산 1 | E28: 초안산스포츠타운 축구장 | F28: 노원구 | G28: 노원구서비스공단 | H28: 6630 | I28: 6630 | L28: 인조잔디 | M28: 65 | N28: 102 | O28: 6630 | P28: 1 | Q28: 500 | R28: 500 | S28: 콘크리트, 목재 | T28: - | V28: 2001 (2007보수)
C29: 노원구 | E29: 불암스포츠타운 축구장 | F29: 노원구 | G29: 노원구 서비스공단 | H29: 38000 | I29: 6825 | L29: 인조잔디 | M29: 68 | N29: 100 | O29: 6825 | P29: 1 | Q29: 500 | R29: 500 | V29: 2009
C30: 노원구 | E30: 수락산스포츠타운 축구장 | F30: 노원구 | G30: 노원구 서비스공단 | I30: 5400 | L30: 인조잔디 | M30: 60 | N30: 90 | O30: 5400 | P30: 1 | V30: 2022
C31: 은평구 | D31: 은평구 진관1로 46 | E31: 은평구립축구장 | F31: 은평구 | G31: 은평구시설관리공단 | H31: 9700 | I31: 9700 | K31: 3534 | L31: 인조잔디 | M31: 64 | N31: 100 | O31: 6930 | P31: 1 | Q31: 700 | R31: 700 | S31: 계단식 | T31: 철근콘크리트 | V31: 2006 | AB31: 8181 | AC31: 8181
C32: 서대문구 | E32: 서대문구립 인조잔디 구장 | F32: 서대문구 | G32: 서대문구시설관리공단 | H32: 7560 | I32: 6526 | L32: 인조잔디 | M32: 60 | N32: 94 | O32: 5640 | P32: 1 | Q32: 126 | R32: 126 | S32: 계단식 | T32: 철제 | V32: 2004 | AB32: 845
C33: 서대문구 | E33: 서대문돌산 인조잔디구장 | F33: 서대문구 | G33: 서대문구 시설관리공단 | H33: 1568 | I33: 1568 | L33: 인조잔디 | M33: 32 | N33: 49 | O33: 1568 | P33: 1 | V33: 2013
C34: 마포구 | D34: 망원동 450-3 | E34: 망원유수지 대축구장 | F34: 마포구 | G34: 마포구 | I34: 21600 | L34: 마사토 | V34: 2008
C35: 마포구 | D35: 망원동 450-3 | E35: 망원유수지 소축구장 | F35: 마포구 | G35: 마포구체육회 | I35: 6242 | L35: 인조잔디 | V35: 2024 | W35: 1793
C36: 마포구 | E36: 한강공원 망원지구 축구장 | F36: 서울시 | G36: 미래한강본부 | H36: 8400 | I36: 8128 | L36: 토사 | M36: 60 | N36: 100 | O36: 6000 | P36: 1 | Q36: 0 | R36: 0 | S36: 0 | T36: 0 | V36: 1993 | AB36: 132
A37: 9 | C37: 마포구 | D37: 서울시 성산동 515 | E37: 서울월드컵경기장 | F37: 서울시 | G37: 서울시설공단 | H37: 216712 | I37: 216712 | J37: 58724 | K37: 166678 | L37: 하이브리드 잔디 | M37: 78 | N37: 117 | O37: 9126 | P37: 1 | Q37: 66704 | R37: 66704 | S37: 계단식 ("ㅁ"자형) | T37: RC&SRC&S | V37: 2001 | X37: 600억원 | Y37: 800억원 | AB37: 660 | AC37: 660000 | AE37: 2 | AG37: 322 | AH37: 2,289Lx | AI37: 34백만원
A38: 10 | C38: 마포구 | D38: 서울시 성산동 515 | E38: 서울월드컵경기장 보조경기장 | F38: 서울시 | G38: 서울시설공단 | I38: 12271 | J38: 765 | L38: 인조잔디 | M38: 82.6 | N38: 120 | O38: 9910 | P38: 1 | Q38: 1012 | R38: 1012 | S38: 계단식 (일자형) | T38: RC&S | V38: 2001 | AB38: 주경기장에 포함 | AV38: 일반석(992석) 장애인석(20석)
A39: 11 | C39: 마포구 | E39: 월드컵공원 인조잔디축구장 | F39: 서울시 | G39: 마포구 | H39: 8510 | I39: 8510 | L39: 인조잔디 | M39: 66 | N39: 102 | O39: 6732 | P39: 1 | Q39: 100 | R39: 100 | S39: 스탠드 | V39: 2005 | AB39: 1186
C40: 고양시 덕양구 | D40: 경기도 고양시 덕양구 대덕로426 | E40: 난지물재생센터 축구장 | F40: 서울시 | G40: 난지물재생센터 | H40: 3600 | I40: 6400 | L40: 인조잔디 | M40: 40 | N40: 90 | O40: 3600 | P40: 1 | V40: 2011
...

Sheet 3.하키장
B1: 3. 하키장 | T1: (단위 : ㎡, 백만원, 명)
A2: 일련번호 | B2: 시도 | C2: 시군구 | D2: 주소 | E2: 시설명 | F2: 소유기관 | G2: 운영조직 (연락처) | H2: 관리주체 | I2: 관리인원 | J2: 부지면적 | K2: 건축면적 | L2: 연면적 | M2: 경기장 | Q2: 관람석 | U2: 국제규격 (O,X) | V2: 준공연도 | W2: 건 설 사업비 | AD2: 개보수연도 | AF2: 부대시설 | AL2: 부대운동시설 | AX2: 비고
M3: 필드 | Q3: 좌석수 | R3: 수용인원 | S3: 좌석형태 | T3: 건축구조 | AD3: 1차 | AE3: 2차 | AF3: 전광판 | AH3: 조명탑 | AK3: 기타 | AL3: 종목1 | AQ3: 종목2 | AV3: 종목3
M4: 바닥재료 | N4: 폭 | O4: 길이 | P4: 면적 | AF4: 개소수 | AG4: 설치비 | AH4: 개소수 | AI4: 조도 | AJ4: 설치비 | AL4: 종목 | AM4: 면수 | AN4: 면적 | AO4: 시설구성 | AP4: 관리운영 | AQ4: 종목 | AR4: 면수 | AS4: 면적 | AT4: 시설구성 | AU4: 관리운영 | AV4: 종목 | AW4: 면수
B5: 전국 | C5: 계 | E5: =COUNTA(E7,E9,E11,E13:E14,E16:E18,E20:E21,E23:E24,E26:E26,E28,E29,E31:E32,E34) -> 18 | J5: =SUM(J7,J9,J11,J13:J14,J16:J18,J20:J21,J23:J24,J26:J26,J28:J29,J31:J32,J34) -> 1169357 | K5: =SUM(K7,K9,K11,K13:K14,K16:K18,K20:K21,K23:K24,K26:K26,K28:K29,K31:K32,K34) -> 20510.36 | L5: =SUM(L7,L9,L11,L13:L14,L16:L18,L20:L21,L23:L24,L26:L26,L28:L29,L31:L32,L34) -> 28890.24
B6: 서울 | C6: 소 계 | E6: =COUNTA(E7) -> 1 | J6: =SUM(J7) -> 183879 | K6: =SUM(K7) -> 0 | L6: =SUM(L7) -> 0 | N6: =SUM(N7) -> 70 | O6: =SUM(O7) -> 105 | P6: =SUM(P7) -> 7350 | R6: =SUM(R7) -> 0
C7: 노원구 | E7: 태릉선수촌 하키경기장 | F7: 대한체육회 | H7: 대한체육회 | J7: 183879 | M7: 인조잔디 | N7: 70 | O7: 105 | P7: 7350 | R7: - | T7: - | V7: 1984 | AC7: 2348 | AX7: 육상트랙
B8: 부산 | C8: 소 계 | E8: =COUNTA(E9) -> 1 | J8: =SUM(J9) -> 18310 | K8: =SUM(K9) -> 1227 | L8: =SUM(L9) -> 1898 | N8: =SUM(N9) -> 71 | O8: =SUM(O9) -> 108 | P8: =SUM(P9) -> 15158 | R8: =SUM(R9) -> 2612
A9: 1 | C9: 강서구 | D9: 대저동 2155 | E9: 강서체육공원 하키경기장 | F9: 부산시 | G9: 체육시설관리사업소 강서체육공원 (051-970-1211) | H9: 체육시설관리 사업소 | J9: 18310 | K9: 1227 | L9: 1898 | M9: 인조잔디 | N9: 71 | O9: 108 | P9: 15158 | Q9: 2597 | R9: 2612 | S9: 의자식 | T9: 철근콘크리트 | V9: 2002 | AC9: 13588 | AF9: 1 | AG9: 72
B10: 대구 | C10: 소 계 | E10: =COUNTA(E11) -> 1 | J10: =SUM(J11) -> 50760 | K10: =SUM(K11) -> 297 | L10: =SUM(L11) -> 297 | N10: =SUM(N11) -> 72 | O10: =SUM(O11) -> 108 | P10: =SUM(P11) -> 7776 | R10: =SUM(R11) -> 1560
C11: 동구 | E11: 안심 하키장 | F11: 대구시 | H11: 대구환경공단 (동부사업소) | J11: 50760 | K11: 297 | L11: 297 | M11: 인조잔디 | N11: 72 | O11: 108 | P11: 7776 | R11: 1560 | T11: 야외 계단식 | V11: 2001 | AC11: 632
B12: 인천 | C12: 소 계 | E12: =COUNTA(E13:E14) -> 2 | J12: =SUM(J13:J14) -> 255935 | K12: =SUM(K13:K14) -> 6414 | L12: =SUM(L13:L14) -> 6762 | N12: =SUM(N13:N14) -> 122 | O12: =SUM(O13:O14) -> 197.5 | P12: =SUM(P13:P14) -> 12081.2 | R12: =SUM(R13:R14) -> 5138
C13: 미추홀구 | E13: 다목적경기장 (하키장) | F13: 인천시 | H13: 위탁 (인천시체육회) | J13: 13451 | K13: 239 | L13: 239 | M13: 인조잔디 | N13: 63 | O13: 101 | P13: 6388.2 | V13: 2005 | AC13: 1934
C14: 연수구 | E14: 선학하키경기장 | F14: 인천시 | H14: 위탁 (인천시체육회) | J14: 242484 | K14: 6175 | L14: 6523 | M14: 인조잔디 | N14: 59 | O14: 96.5 | P14: 5693 | R14: 5138 | V14: 2014
A15: 1 | B15: 경기 | C15: 소 계 | E15: =COUNTA(E16:E18) -> 3 | J15: =SUM(J16:J18) -> 44017 | K15: =SUM(K16:K18) -> 1294 | L15: =SUM(L16:L18) -> 6903 | N15: =SUM(N16:N18) -> 144 | O15: =SUM(O16:O18) -> 206 | P15: =SUM(P16:P18) -> 11546 | R15: =SUM(R16:R18) -> 3400
C16: 용인시 | D16: 경기도 용인시 기흥구 흥덕1로 43 | E16: 영덕레스피아 인라인하키장 | F16: 용인시 | G16: 용인시 기흥구청 (6193-6051) | H16: 용인시 | J16: 24000 | K16: 428 | L16: 428 | M16: 우레탄 | N16: 28 | O16: 15 | P16: 428 | V16: 2020
C17: 성남시 | D17: 경기도 성남시 중원구 성남동3110 | E17: 성남 하키장 | F17: 성남시 | G17: 종합운동장관리사무소031)729-5870 | H17: 성남도시개발공사 | I17: 1 | J17: 13255 | K17: 866 | L17: 6475 | M17: 인조잔디 | N17: 58 | O17: 100 | P17: 5840 | Q17: 1993 | R17: 2500 | S17: 의자식 | T17: 철근콘크리트 | V17: 1997 | W17: 9 | AC17: 900 | AX17: 종합운동장내
C18: 평택시 | D18: 경기도 평택시 합정동 산28 | E18: 소사벌레포츠 하키장 | F18: 평택시 | G18: 종합운동장관리사무소031)729-5870 | H18: 평택시(체육진흥과) | I18: 1 | J18: 6762 | M18: 인조잔디 | N18: 58 | O18: 91 | P18: 5278 | Q18: 1993 | R18: 900 | S18: 의자식 | T18: 철근콘크리트 | V18: 2007 | W18: 9 | AC18: 1100 | AY18: (수정) 시설명 수정
A19: 1 | B19: 강원 | C19: 소 계 | E19: =COUNTA(E20:E21) -> 2 | J19: =SUM(J20:J21) -> 38157 | K19: =SUM(K20:K21) -> 332.86 | L19: =SUM(L20:L21) -> 483.24 | N19: =SUM(N20:N21) -> 135 | O19: =SUM(O20:O21) -> 207 | P19: =SUM(P20:P21) -> 17344 | Q19: =SUM(Q20:Q21) -> 1600 | R19: =SUM(R20:R21) -> 1600 | AC19: =SUM(AC20:AC21) -> 9955
